python: can't open file '/home/vagrant/batching-request/src/azure_container/client_overhead/test/./nat/proxy.py': [Errno 2] No such file or directory
python: can't open file '/home/vagrant/batching-request/src/azure_container/client_overhead/test/./nat/proxy.py': [Errno 2] No such file or directory
python: can't open file '/home/vagrant/batching-request/src/azure_container/client_overhead/test/./nat/proxy.py': [Errno 2] No such file or directory
python: can't open file '/home/vagrant/batching-request/src/azure_container/client_overhead/test/../nat/proxy.py': [Errno 2] No such file or directory
python: can't open file '/home/vagrant/batching-request/src/azure_container/client_overhead/test/../nat/proxy.py': [Errno 2] No such file or directory
python: can't open file '/home/vagrant/batching-request/src/azure_container/client_overhead/test/../nat/proxy.py': [Errno 2] No such file or directory
[2022-09-21 08:19:24,126] ERROR in app: Exception on /init [POST]
Traceback (most recent call last):
  File "/home/vagrant/miniconda3/lib/python3.9/site-packages/flask/app.py", line 2525, in wsgi_app
    response = self.full_dispatch_request()
  File "/home/vagrant/miniconda3/lib/python3.9/site-packages/flask/app.py", line 1822, in full_dispatch_request
    rv = self.handle_user_exception(e)
  File "/home/vagrant/miniconda3/lib/python3.9/site-packages/flask/app.py", line 1820, in full_dispatch_request
    rv = self.dispatch_request()
  File "/home/vagrant/miniconda3/lib/python3.9/site-packages/flask/app.py", line 1796, in dispatch_request
    return self.ensure_sync(self.view_functions[rule.endpoint])(**view_args)
  File "/home/vagrant/batching-request/src/azure_container/client_overhead/test/../native/proxy.py", line 70, in init
    runner.init()
  File "/home/vagrant/batching-request/src/azure_container/client_overhead/test/../native/proxy.py", line 27, in init
    with open(filename, 'r') as f:
FileNotFoundError: [Errno 2] No such file or directory: './main.py'
127.0.0.1 - - [2022-09-21 08:19:24] "POST /init HTTP/1.1" 500 401 0.005593
127.0.0.1 - - [2022-09-21 08:19:24] "POST /batch_run HTTP/1.1" 200 189 0.074459
[2022-09-21 08:19:24,901] ERROR in app: Exception on /init [POST]
Traceback (most recent call last):
  File "/home/vagrant/miniconda3/lib/python3.9/site-packages/flask/app.py", line 2525, in wsgi_app
    response = self.full_dispatch_request()
  File "/home/vagrant/miniconda3/lib/python3.9/site-packages/flask/app.py", line 1822, in full_dispatch_request
    rv = self.handle_user_exception(e)
  File "/home/vagrant/miniconda3/lib/python3.9/site-packages/flask/app.py", line 1820, in full_dispatch_request
    rv = self.dispatch_request()
  File "/home/vagrant/miniconda3/lib/python3.9/site-packages/flask/app.py", line 1796, in dispatch_request
    return self.ensure_sync(self.view_functions[rule.endpoint])(**view_args)
  File "/home/vagrant/batching-request/src/azure_container/client_overhead/test/../native/proxy.py", line 70, in init
    runner.init()
  File "/home/vagrant/batching-request/src/azure_container/client_overhead/test/../native/proxy.py", line 27, in init
    with open(filename, 'r') as f:
FileNotFoundError: [Errno 2] No such file or directory: './main.py'
127.0.0.1 - - [2022-09-21 08:19:24] "POST /init HTTP/1.1" 500 401 0.002075
127.0.0.1 - - [2022-09-21 08:19:25] "POST /batch_run HTTP/1.1" 200 271 0.143328
[2022-09-21 08:19:25,746] ERROR in app: Exception on /init [POST]
Traceback (most recent call last):
  File "/home/vagrant/miniconda3/lib/python3.9/site-packages/flask/app.py", line 2525, in wsgi_app
    response = self.full_dispatch_request()
  File "/home/vagrant/miniconda3/lib/python3.9/site-packages/flask/app.py", line 1822, in full_dispatch_request
    rv = self.handle_user_exception(e)
  File "/home/vagrant/miniconda3/lib/python3.9/site-packages/flask/app.py", line 1820, in full_dispatch_request
    rv = self.dispatch_request()
  File "/home/vagrant/miniconda3/lib/python3.9/site-packages/flask/app.py", line 1796, in dispatch_request
    return self.ensure_sync(self.view_functions[rule.endpoint])(**view_args)
  File "/home/vagrant/batching-request/src/azure_container/client_overhead/test/../native/proxy.py", line 70, in init
    runner.init()
  File "/home/vagrant/batching-request/src/azure_container/client_overhead/test/../native/proxy.py", line 27, in init
    with open(filename, 'r') as f:
FileNotFoundError: [Errno 2] No such file or directory: './main.py'
127.0.0.1 - - [2022-09-21 08:19:25] "POST /init HTTP/1.1" 500 401 0.005696
127.0.0.1 - - [2022-09-21 08:19:26] "POST /batch_run HTTP/1.1" 200 350 0.769364
[2022-09-21 08:19:27,213] ERROR in app: Exception on /init [POST]
Traceback (most recent call last):
  File "/home/vagrant/miniconda3/lib/python3.9/site-packages/flask/app.py", line 2525, in wsgi_app
    response = self.full_dispatch_request()
  File "/home/vagrant/miniconda3/lib/python3.9/site-packages/flask/app.py", line 1822, in full_dispatch_request
    rv = self.handle_user_exception(e)
  File "/home/vagrant/miniconda3/lib/python3.9/site-packages/flask/app.py", line 1820, in full_dispatch_request
    rv = self.dispatch_request()
  File "/home/vagrant/miniconda3/lib/python3.9/site-packages/flask/app.py", line 1796, in dispatch_request
    return self.ensure_sync(self.view_functions[rule.endpoint])(**view_args)
  File "/home/vagrant/batching-request/src/azure_container/client_overhead/test/../native/proxy.py", line 70, in init
    runner.init()
  File "/home/vagrant/batching-request/src/azure_container/client_overhead/test/../native/proxy.py", line 27, in init
    with open(filename, 'r') as f:
FileNotFoundError: [Errno 2] No such file or directory: './main.py'
127.0.0.1 - - [2022-09-21 08:19:27] "POST /init HTTP/1.1" 500 401 0.005646
127.0.0.1 - - [2022-09-21 08:19:27] "POST /batch_run HTTP/1.1" 200 109 0.709624
[2022-09-21 08:19:32,869] ERROR in app: Exception on /init [POST]
Traceback (most recent call last):
  File "/home/vagrant/miniconda3/lib/python3.9/site-packages/flask/app.py", line 2525, in wsgi_app
    response = self.full_dispatch_request()
  File "/home/vagrant/miniconda3/lib/python3.9/site-packages/flask/app.py", line 1822, in full_dispatch_request
    rv = self.handle_user_exception(e)
  File "/home/vagrant/miniconda3/lib/python3.9/site-packages/flask/app.py", line 1820, in full_dispatch_request
    rv = self.dispatch_request()
  File "/home/vagrant/miniconda3/lib/python3.9/site-packages/flask/app.py", line 1796, in dispatch_request
    return self.ensure_sync(self.view_functions[rule.endpoint])(**view_args)
  File "/home/vagrant/batching-request/src/azure_container/client_overhead/test/../optimize/proxy.py", line 103, in init
    runner.init()
  File "/home/vagrant/batching-request/src/azure_container/client_overhead/test/../optimize/proxy.py", line 30, in init
    with open(filename, 'r') as f:
FileNotFoundError: [Errno 2] No such file or directory: './main.py'
127.0.0.1 - - [2022-09-21 08:19:32] "POST /init HTTP/1.1" 500 401 0.005512
127.0.0.1 - - [2022-09-21 08:19:32] "POST /batch_run HTTP/1.1" 200 186 0.056483
[2022-09-21 08:19:33,647] ERROR in app: Exception on /init [POST]
Traceback (most recent call last):
  File "/home/vagrant/miniconda3/lib/python3.9/site-packages/flask/app.py", line 2525, in wsgi_app
    response = self.full_dispatch_request()
  File "/home/vagrant/miniconda3/lib/python3.9/site-packages/flask/app.py", line 1822, in full_dispatch_request
    rv = self.handle_user_exception(e)
  File "/home/vagrant/miniconda3/lib/python3.9/site-packages/flask/app.py", line 1820, in full_dispatch_request
    rv = self.dispatch_request()
  File "/home/vagrant/miniconda3/lib/python3.9/site-packages/flask/app.py", line 1796, in dispatch_request
    return self.ensure_sync(self.view_functions[rule.endpoint])(**view_args)
  File "/home/vagrant/batching-request/src/azure_container/client_overhead/test/../optimize/proxy.py", line 103, in init
    runner.init()
  File "/home/vagrant/batching-request/src/azure_container/client_overhead/test/../optimize/proxy.py", line 30, in init
    with open(filename, 'r') as f:
FileNotFoundError: [Errno 2] No such file or directory: './main.py'
127.0.0.1 - - [2022-09-21 08:19:33] "POST /init HTTP/1.1" 500 401 0.005709
127.0.0.1 - - [2022-09-21 08:19:33] "POST /batch_run HTTP/1.1" 200 262 0.073864
[2022-09-21 08:19:34,433] ERROR in app: Exception on /init [POST]
Traceback (most recent call last):
  File "/home/vagrant/miniconda3/lib/python3.9/site-packages/flask/app.py", line 2525, in wsgi_app
    response = self.full_dispatch_request()
  File "/home/vagrant/miniconda3/lib/python3.9/site-packages/flask/app.py", line 1822, in full_dispatch_request
    rv = self.handle_user_exception(e)
  File "/home/vagrant/miniconda3/lib/python3.9/site-packages/flask/app.py", line 1820, in full_dispatch_request
    rv = self.dispatch_request()
  File "/home/vagrant/miniconda3/lib/python3.9/site-packages/flask/app.py", line 1796, in dispatch_request
    return self.ensure_sync(self.view_functions[rule.endpoint])(**view_args)
  File "/home/vagrant/batching-request/src/azure_container/client_overhead/test/../optimize/proxy.py", line 103, in init
    runner.init()
  File "/home/vagrant/batching-request/src/azure_container/client_overhead/test/../optimize/proxy.py", line 30, in init
    with open(filename, 'r') as f:
FileNotFoundError: [Errno 2] No such file or directory: './main.py'
127.0.0.1 - - [2022-09-21 08:19:34] "POST /init HTTP/1.1" 500 401 0.006185
127.0.0.1 - - [2022-09-21 08:19:34] "POST /batch_run HTTP/1.1" 200 343 0.095001
[2022-09-21 08:19:35,737] ERROR in app: Exception on /init [POST]
Traceback (most recent call last):
  File "/home/vagrant/miniconda3/lib/python3.9/site-packages/flask/app.py", line 2525, in wsgi_app
    response = self.full_dispatch_request()
  File "/home/vagrant/miniconda3/lib/python3.9/site-packages/flask/app.py", line 1822, in full_dispatch_request
    rv = self.handle_user_exception(e)
  File "/home/vagrant/miniconda3/lib/python3.9/site-packages/flask/app.py", line 1820, in full_dispatch_request
    rv = self.dispatch_request()
  File "/home/vagrant/miniconda3/lib/python3.9/site-packages/flask/app.py", line 1796, in dispatch_request
    return self.ensure_sync(self.view_functions[rule.endpoint])(**view_args)
  File "/home/vagrant/batching-request/src/azure_container/client_overhead/test/../optimize/proxy.py", line 103, in init
    runner.init()
  File "/home/vagrant/batching-request/src/azure_container/client_overhead/test/../optimize/proxy.py", line 30, in init
    with open(filename, 'r') as f:
FileNotFoundError: [Errno 2] No such file or directory: './main.py'
127.0.0.1 - - [2022-09-21 08:19:35] "POST /init HTTP/1.1" 500 401 0.005393
127.0.0.1 - - [2022-09-21 08:19:35] "POST /batch_run HTTP/1.1" 200 419 0.150380
[2022-09-21 08:19:36,581] ERROR in app: Exception on /init [POST]
Traceback (most recent call last):
  File "/home/vagrant/miniconda3/lib/python3.9/site-packages/flask/app.py", line 2525, in wsgi_app
    response = self.full_dispatch_request()
  File "/home/vagrant/miniconda3/lib/python3.9/site-packages/flask/app.py", line 1822, in full_dispatch_request
    rv = self.handle_user_exception(e)
  File "/home/vagrant/miniconda3/lib/python3.9/site-packages/flask/app.py", line 1820, in full_dispatch_request
    rv = self.dispatch_request()
  File "/home/vagrant/miniconda3/lib/python3.9/site-packages/flask/app.py", line 1796, in dispatch_request
    return self.ensure_sync(self.view_functions[rule.endpoint])(**view_args)
  File "/home/vagrant/batching-request/src/azure_container/client_overhead/test/../optimize/proxy.py", line 103, in init
    runner.init()
  File "/home/vagrant/batching-request/src/azure_container/client_overhead/test/../optimize/proxy.py", line 30, in init
    with open(filename, 'r') as f:
FileNotFoundError: [Errno 2] No such file or directory: './main.py'
127.0.0.1 - - [2022-09-21 08:19:36] "POST /init HTTP/1.1" 500 401 0.005691
127.0.0.1 - - [2022-09-21 08:19:36] "POST /batch_run HTTP/1.1" 200 502 0.314989
[2022-09-21 08:19:37,582] ERROR in app: Exception on /init [POST]
Traceback (most recent call last):
  File "/home/vagrant/miniconda3/lib/python3.9/site-packages/flask/app.py", line 2525, in wsgi_app
    response = self.full_dispatch_request()
  File "/home/vagrant/miniconda3/lib/python3.9/site-packages/flask/app.py", line 1822, in full_dispatch_request
    rv = self.handle_user_exception(e)
  File "/home/vagrant/miniconda3/lib/python3.9/site-packages/flask/app.py", line 1820, in full_dispatch_request
    rv = self.dispatch_request()
  File "/home/vagrant/miniconda3/lib/python3.9/site-packages/flask/app.py", line 1796, in dispatch_request
    return self.ensure_sync(self.view_functions[rule.endpoint])(**view_args)
  File "/home/vagrant/batching-request/src/azure_container/client_overhead/test/../optimize/proxy.py", line 103, in init
    runner.init()
  File "/home/vagrant/batching-request/src/azure_container/client_overhead/test/../optimize/proxy.py", line 30, in init
    with open(filename, 'r') as f:
FileNotFoundError: [Errno 2] No such file or directory: './main.py'
127.0.0.1 - - [2022-09-21 08:19:37] "POST /init HTTP/1.1" 500 401 0.005675
127.0.0.1 - - [2022-09-21 08:19:37] "POST /batch_run HTTP/1.1" 200 571 0.133143
[2022-09-21 08:19:38,425] ERROR in app: Exception on /init [POST]
Traceback (most recent call last):
  File "/home/vagrant/miniconda3/lib/python3.9/site-packages/flask/app.py", line 2525, in wsgi_app
    response = self.full_dispatch_request()
  File "/home/vagrant/miniconda3/lib/python3.9/site-packages/flask/app.py", line 1822, in full_dispatch_request
    rv = self.handle_user_exception(e)
  File "/home/vagrant/miniconda3/lib/python3.9/site-packages/flask/app.py", line 1820, in full_dispatch_request
    rv = self.dispatch_request()
  File "/home/vagrant/miniconda3/lib/python3.9/site-packages/flask/app.py", line 1796, in dispatch_request
    return self.ensure_sync(self.view_functions[rule.endpoint])(**view_args)
  File "/home/vagrant/batching-request/src/azure_container/client_overhead/test/../optimize/proxy.py", line 103, in init
    runner.init()
  File "/home/vagrant/batching-request/src/azure_container/client_overhead/test/../optimize/proxy.py", line 30, in init
    with open(filename, 'r') as f:
FileNotFoundError: [Errno 2] No such file or directory: './main.py'
127.0.0.1 - - [2022-09-21 08:19:38] "POST /init HTTP/1.1" 500 401 0.006053
127.0.0.1 - - [2022-09-21 08:19:38] "POST /batch_run HTTP/1.1" 200 636 0.183462
[2022-09-21 08:19:39,299] ERROR in app: Exception on /init [POST]
Traceback (most recent call last):
  File "/home/vagrant/miniconda3/lib/python3.9/site-packages/flask/app.py", line 2525, in wsgi_app
    response = self.full_dispatch_request()
  File "/home/vagrant/miniconda3/lib/python3.9/site-packages/flask/app.py", line 1822, in full_dispatch_request
    rv = self.handle_user_exception(e)
  File "/home/vagrant/miniconda3/lib/python3.9/site-packages/flask/app.py", line 1820, in full_dispatch_request
    rv = self.dispatch_request()
  File "/home/vagrant/miniconda3/lib/python3.9/site-packages/flask/app.py", line 1796, in dispatch_request
    return self.ensure_sync(self.view_functions[rule.endpoint])(**view_args)
  File "/home/vagrant/batching-request/src/azure_container/client_overhead/test/../optimize/proxy.py", line 103, in init
    runner.init()
  File "/home/vagrant/batching-request/src/azure_container/client_overhead/test/../optimize/proxy.py", line 30, in init
    with open(filename, 'r') as f:
FileNotFoundError: [Errno 2] No such file or directory: './main.py'
127.0.0.1 - - [2022-09-21 08:19:39] "POST /init HTTP/1.1" 500 401 0.005998
127.0.0.1 - - [2022-09-21 08:19:39] "POST /batch_run HTTP/1.1" 200 732 0.184582
[2022-09-21 08:28:05,320] ERROR in app: Exception on /init [POST]
Traceback (most recent call last):
  File "/home/vagrant/miniconda3/lib/python3.9/site-packages/flask/app.py", line 2525, in wsgi_app
    response = self.full_dispatch_request()
  File "/home/vagrant/miniconda3/lib/python3.9/site-packages/flask/app.py", line 1822, in full_dispatch_request
    rv = self.handle_user_exception(e)
  File "/home/vagrant/miniconda3/lib/python3.9/site-packages/flask/app.py", line 1820, in full_dispatch_request
    rv = self.dispatch_request()
  File "/home/vagrant/miniconda3/lib/python3.9/site-packages/flask/app.py", line 1796, in dispatch_request
    return self.ensure_sync(self.view_functions[rule.endpoint])(**view_args)
  File "/home/vagrant/batching-request/src/azure_container/client_overhead/test/../native/proxy.py", line 70, in init
    runner.init()
  File "/home/vagrant/batching-request/src/azure_container/client_overhead/test/../native/proxy.py", line 27, in init
    with open(filename, 'r') as f:
FileNotFoundError: [Errno 2] No such file or directory: './main.py'
127.0.0.1 - - [2022-09-21 08:28:05] "POST /init HTTP/1.1" 500 401 0.005579
127.0.0.1 - - [2022-09-21 08:28:05] "POST /batch_run HTTP/1.1" 200 184 0.073216
[2022-09-21 08:28:06,096] ERROR in app: Exception on /init [POST]
Traceback (most recent call last):
  File "/home/vagrant/miniconda3/lib/python3.9/site-packages/flask/app.py", line 2525, in wsgi_app
    response = self.full_dispatch_request()
  File "/home/vagrant/miniconda3/lib/python3.9/site-packages/flask/app.py", line 1822, in full_dispatch_request
    rv = self.handle_user_exception(e)
  File "/home/vagrant/miniconda3/lib/python3.9/site-packages/flask/app.py", line 1820, in full_dispatch_request
    rv = self.dispatch_request()
  File "/home/vagrant/miniconda3/lib/python3.9/site-packages/flask/app.py", line 1796, in dispatch_request
    return self.ensure_sync(self.view_functions[rule.endpoint])(**view_args)
  File "/home/vagrant/batching-request/src/azure_container/client_overhead/test/../native/proxy.py", line 70, in init
    runner.init()
  File "/home/vagrant/batching-request/src/azure_container/client_overhead/test/../native/proxy.py", line 27, in init
    with open(filename, 'r') as f:
FileNotFoundError: [Errno 2] No such file or directory: './main.py'
127.0.0.1 - - [2022-09-21 08:28:06] "POST /init HTTP/1.1" 500 401 0.005778
127.0.0.1 - - [2022-09-21 08:28:06] "POST /batch_run HTTP/1.1" 200 271 0.142852
[2022-09-21 08:28:06,940] ERROR in app: Exception on /init [POST]
Traceback (most recent call last):
  File "/home/vagrant/miniconda3/lib/python3.9/site-packages/flask/app.py", line 2525, in wsgi_app
    response = self.full_dispatch_request()
  File "/home/vagrant/miniconda3/lib/python3.9/site-packages/flask/app.py", line 1822, in full_dispatch_request
    rv = self.handle_user_exception(e)
  File "/home/vagrant/miniconda3/lib/python3.9/site-packages/flask/app.py", line 1820, in full_dispatch_request
    rv = self.dispatch_request()
  File "/home/vagrant/miniconda3/lib/python3.9/site-packages/flask/app.py", line 1796, in dispatch_request
    return self.ensure_sync(self.view_functions[rule.endpoint])(**view_args)
  File "/home/vagrant/batching-request/src/azure_container/client_overhead/test/../native/proxy.py", line 70, in init
    runner.init()
  File "/home/vagrant/batching-request/src/azure_container/client_overhead/test/../native/proxy.py", line 27, in init
    with open(filename, 'r') as f:
FileNotFoundError: [Errno 2] No such file or directory: './main.py'
127.0.0.1 - - [2022-09-21 08:28:06] "POST /init HTTP/1.1" 500 401 0.005797
127.0.0.1 - - [2022-09-21 08:28:07] "POST /batch_run HTTP/1.1" 200 351 0.268438
[2022-09-21 08:28:07,905] ERROR in app: Exception on /init [POST]
Traceback (most recent call last):
  File "/home/vagrant/miniconda3/lib/python3.9/site-packages/flask/app.py", line 2525, in wsgi_app
    response = self.full_dispatch_request()
  File "/home/vagrant/miniconda3/lib/python3.9/site-packages/flask/app.py", line 1822, in full_dispatch_request
    rv = self.handle_user_exception(e)
  File "/home/vagrant/miniconda3/lib/python3.9/site-packages/flask/app.py", line 1820, in full_dispatch_request
    rv = self.dispatch_request()
  File "/home/vagrant/miniconda3/lib/python3.9/site-packages/flask/app.py", line 1796, in dispatch_request
    return self.ensure_sync(self.view_functions[rule.endpoint])(**view_args)
  File "/home/vagrant/batching-request/src/azure_container/client_overhead/test/../native/proxy.py", line 70, in init
    runner.init()
  File "/home/vagrant/batching-request/src/azure_container/client_overhead/test/../native/proxy.py", line 27, in init
    with open(filename, 'r') as f:
FileNotFoundError: [Errno 2] No such file or directory: './main.py'
127.0.0.1 - - [2022-09-21 08:28:07] "POST /init HTTP/1.1" 500 401 0.002168
127.0.0.1 - - [2022-09-21 08:28:08] "POST /batch_run HTTP/1.1" 200 432 0.349691
[2022-09-21 08:29:01,917] ERROR in app: Exception on /init [POST]
Traceback (most recent call last):
  File "/home/vagrant/miniconda3/lib/python3.9/site-packages/flask/app.py", line 2525, in wsgi_app
    response = self.full_dispatch_request()
  File "/home/vagrant/miniconda3/lib/python3.9/site-packages/flask/app.py", line 1822, in full_dispatch_request
    rv = self.handle_user_exception(e)
  File "/home/vagrant/miniconda3/lib/python3.9/site-packages/flask/app.py", line 1820, in full_dispatch_request
    rv = self.dispatch_request()
  File "/home/vagrant/miniconda3/lib/python3.9/site-packages/flask/app.py", line 1796, in dispatch_request
    return self.ensure_sync(self.view_functions[rule.endpoint])(**view_args)
  File "/home/vagrant/batching-request/src/azure_container/client_overhead/test/../native/proxy.py", line 70, in init
    runner.init()
  File "/home/vagrant/batching-request/src/azure_container/client_overhead/test/../native/proxy.py", line 27, in init
    with open(filename, 'r') as f:
FileNotFoundError: [Errno 2] No such file or directory: './main.py'
127.0.0.1 - - [2022-09-21 08:29:01] "POST /init HTTP/1.1" 500 401 0.005742
127.0.0.1 - - [2022-09-21 08:29:02] "POST /batch_run HTTP/1.1" 200 188 0.086140
[2022-09-21 08:29:02,730] ERROR in app: Exception on /init [POST]
Traceback (most recent call last):
  File "/home/vagrant/miniconda3/lib/python3.9/site-packages/flask/app.py", line 2525, in wsgi_app
    response = self.full_dispatch_request()
  File "/home/vagrant/miniconda3/lib/python3.9/site-packages/flask/app.py", line 1822, in full_dispatch_request
    rv = self.handle_user_exception(e)
  File "/home/vagrant/miniconda3/lib/python3.9/site-packages/flask/app.py", line 1820, in full_dispatch_request
    rv = self.dispatch_request()
  File "/home/vagrant/miniconda3/lib/python3.9/site-packages/flask/app.py", line 1796, in dispatch_request
    return self.ensure_sync(self.view_functions[rule.endpoint])(**view_args)
  File "/home/vagrant/batching-request/src/azure_container/client_overhead/test/../native/proxy.py", line 70, in init
    runner.init()
  File "/home/vagrant/batching-request/src/azure_container/client_overhead/test/../native/proxy.py", line 27, in init
    with open(filename, 'r') as f:
FileNotFoundError: [Errno 2] No such file or directory: './main.py'
127.0.0.1 - - [2022-09-21 08:29:02] "POST /init HTTP/1.1" 500 401 0.002087
127.0.0.1 - - [2022-09-21 08:29:02] "POST /batch_run HTTP/1.1" 200 268 0.154428
[2022-09-21 08:29:03,609] ERROR in app: Exception on /init [POST]
Traceback (most recent call last):
  File "/home/vagrant/miniconda3/lib/python3.9/site-packages/flask/app.py", line 2525, in wsgi_app
    response = self.full_dispatch_request()
  File "/home/vagrant/miniconda3/lib/python3.9/site-packages/flask/app.py", line 1822, in full_dispatch_request
    rv = self.handle_user_exception(e)
  File "/home/vagrant/miniconda3/lib/python3.9/site-packages/flask/app.py", line 1820, in full_dispatch_request
    rv = self.dispatch_request()
  File "/home/vagrant/miniconda3/lib/python3.9/site-packages/flask/app.py", line 1796, in dispatch_request
    return self.ensure_sync(self.view_functions[rule.endpoint])(**view_args)
  File "/home/vagrant/batching-request/src/azure_container/client_overhead/test/../native/proxy.py", line 70, in init
    runner.init()
  File "/home/vagrant/batching-request/src/azure_container/client_overhead/test/../native/proxy.py", line 27, in init
    with open(filename, 'r') as f:
FileNotFoundError: [Errno 2] No such file or directory: './main.py'
127.0.0.1 - - [2022-09-21 08:29:03] "POST /init HTTP/1.1" 500 401 0.005966
127.0.0.1 - - [2022-09-21 08:29:03] "POST /batch_run HTTP/1.1" 200 352 0.282186
[2022-09-21 08:29:04,614] ERROR in app: Exception on /init [POST]
Traceback (most recent call last):
  File "/home/vagrant/miniconda3/lib/python3.9/site-packages/flask/app.py", line 2525, in wsgi_app
    response = self.full_dispatch_request()
  File "/home/vagrant/miniconda3/lib/python3.9/site-packages/flask/app.py", line 1822, in full_dispatch_request
    rv = self.handle_user_exception(e)
  File "/home/vagrant/miniconda3/lib/python3.9/site-packages/flask/app.py", line 1820, in full_dispatch_request
    rv = self.dispatch_request()
  File "/home/vagrant/miniconda3/lib/python3.9/site-packages/flask/app.py", line 1796, in dispatch_request
    return self.ensure_sync(self.view_functions[rule.endpoint])(**view_args)
  File "/home/vagrant/batching-request/src/azure_container/client_overhead/test/../native/proxy.py", line 70, in init
    runner.init()
  File "/home/vagrant/batching-request/src/azure_container/client_overhead/test/../native/proxy.py", line 27, in init
    with open(filename, 'r') as f:
FileNotFoundError: [Errno 2] No such file or directory: './main.py'
127.0.0.1 - - [2022-09-21 08:29:04] "POST /init HTTP/1.1" 500 401 0.005665
127.0.0.1 - - [2022-09-21 08:29:04] "POST /batch_run HTTP/1.1" 200 435 0.306302
[2022-09-21 08:29:05,646] ERROR in app: Exception on /init [POST]
Traceback (most recent call last):
  File "/home/vagrant/miniconda3/lib/python3.9/site-packages/flask/app.py", line 2525, in wsgi_app
    response = self.full_dispatch_request()
  File "/home/vagrant/miniconda3/lib/python3.9/site-packages/flask/app.py", line 1822, in full_dispatch_request
    rv = self.handle_user_exception(e)
  File "/home/vagrant/miniconda3/lib/python3.9/site-packages/flask/app.py", line 1820, in full_dispatch_request
    rv = self.dispatch_request()
  File "/home/vagrant/miniconda3/lib/python3.9/site-packages/flask/app.py", line 1796, in dispatch_request
    return self.ensure_sync(self.view_functions[rule.endpoint])(**view_args)
  File "/home/vagrant/batching-request/src/azure_container/client_overhead/test/../native/proxy.py", line 70, in init
    runner.init()
  File "/home/vagrant/batching-request/src/azure_container/client_overhead/test/../native/proxy.py", line 27, in init
    with open(filename, 'r') as f:
FileNotFoundError: [Errno 2] No such file or directory: './main.py'
127.0.0.1 - - [2022-09-21 08:29:05] "POST /init HTTP/1.1" 500 401 0.005757
127.0.0.1 - - [2022-09-21 08:29:07] "POST /batch_run HTTP/1.1" 200 507 1.895524
[2022-09-21 08:29:08,268] ERROR in app: Exception on /init [POST]
Traceback (most recent call last):
  File "/home/vagrant/miniconda3/lib/python3.9/site-packages/flask/app.py", line 2525, in wsgi_app
    response = self.full_dispatch_request()
  File "/home/vagrant/miniconda3/lib/python3.9/site-packages/flask/app.py", line 1822, in full_dispatch_request
    rv = self.handle_user_exception(e)
  File "/home/vagrant/miniconda3/lib/python3.9/site-packages/flask/app.py", line 1820, in full_dispatch_request
    rv = self.dispatch_request()
  File "/home/vagrant/miniconda3/lib/python3.9/site-packages/flask/app.py", line 1796, in dispatch_request
    return self.ensure_sync(self.view_functions[rule.endpoint])(**view_args)
  File "/home/vagrant/batching-request/src/azure_container/client_overhead/test/../native/proxy.py", line 70, in init
    runner.init()
  File "/home/vagrant/batching-request/src/azure_container/client_overhead/test/../native/proxy.py", line 27, in init
    with open(filename, 'r') as f:
FileNotFoundError: [Errno 2] No such file or directory: './main.py'
127.0.0.1 - - [2022-09-21 08:29:08] "POST /init HTTP/1.1" 500 401 0.006003
127.0.0.1 - - [2022-09-21 08:29:09] "POST /batch_run HTTP/1.1" 200 579 0.808215
[2022-09-21 08:29:09,786] ERROR in app: Exception on /init [POST]
Traceback (most recent call last):
  File "/home/vagrant/miniconda3/lib/python3.9/site-packages/flask/app.py", line 2525, in wsgi_app
    response = self.full_dispatch_request()
  File "/home/vagrant/miniconda3/lib/python3.9/site-packages/flask/app.py", line 1822, in full_dispatch_request
    rv = self.handle_user_exception(e)
  File "/home/vagrant/miniconda3/lib/python3.9/site-packages/flask/app.py", line 1820, in full_dispatch_request
    rv = self.dispatch_request()
  File "/home/vagrant/miniconda3/lib/python3.9/site-packages/flask/app.py", line 1796, in dispatch_request
    return self.ensure_sync(self.view_functions[rule.endpoint])(**view_args)
  File "/home/vagrant/batching-request/src/azure_container/client_overhead/test/../native/proxy.py", line 70, in init
    runner.init()
  File "/home/vagrant/batching-request/src/azure_container/client_overhead/test/../native/proxy.py", line 27, in init
    with open(filename, 'r') as f:
FileNotFoundError: [Errno 2] No such file or directory: './main.py'
127.0.0.1 - - [2022-09-21 08:29:09] "POST /init HTTP/1.1" 500 401 0.005481
127.0.0.1 - - [2022-09-21 08:29:10] "POST /batch_run HTTP/1.1" 200 662 0.843351
[2022-09-21 08:29:11,354] ERROR in app: Exception on /init [POST]
Traceback (most recent call last):
  File "/home/vagrant/miniconda3/lib/python3.9/site-packages/flask/app.py", line 2525, in wsgi_app
    response = self.full_dispatch_request()
  File "/home/vagrant/miniconda3/lib/python3.9/site-packages/flask/app.py", line 1822, in full_dispatch_request
    rv = self.handle_user_exception(e)
  File "/home/vagrant/miniconda3/lib/python3.9/site-packages/flask/app.py", line 1820, in full_dispatch_request
    rv = self.dispatch_request()
  File "/home/vagrant/miniconda3/lib/python3.9/site-packages/flask/app.py", line 1796, in dispatch_request
    return self.ensure_sync(self.view_functions[rule.endpoint])(**view_args)
  File "/home/vagrant/batching-request/src/azure_container/client_overhead/test/../native/proxy.py", line 70, in init
    runner.init()
  File "/home/vagrant/batching-request/src/azure_container/client_overhead/test/../native/proxy.py", line 27, in init
    with open(filename, 'r') as f:
FileNotFoundError: [Errno 2] No such file or directory: './main.py'
127.0.0.1 - - [2022-09-21 08:29:11] "POST /init HTTP/1.1" 500 401 0.005552
127.0.0.1 - - [2022-09-21 08:29:12] "POST /batch_run HTTP/1.1" 200 745 0.872863
[2022-09-21 08:29:12,988] ERROR in app: Exception on /init [POST]
Traceback (most recent call last):
  File "/home/vagrant/miniconda3/lib/python3.9/site-packages/flask/app.py", line 2525, in wsgi_app
    response = self.full_dispatch_request()
  File "/home/vagrant/miniconda3/lib/python3.9/site-packages/flask/app.py", line 1822, in full_dispatch_request
    rv = self.handle_user_exception(e)
  File "/home/vagrant/miniconda3/lib/python3.9/site-packages/flask/app.py", line 1820, in full_dispatch_request
    rv = self.dispatch_request()
  File "/home/vagrant/miniconda3/lib/python3.9/site-packages/flask/app.py", line 1796, in dispatch_request
    return self.ensure_sync(self.view_functions[rule.endpoint])(**view_args)
  File "/home/vagrant/batching-request/src/azure_container/client_overhead/test/../native/proxy.py", line 70, in init
    runner.init()
  File "/home/vagrant/batching-request/src/azure_container/client_overhead/test/../native/proxy.py", line 27, in init
    with open(filename, 'r') as f:
FileNotFoundError: [Errno 2] No such file or directory: './main.py'
127.0.0.1 - - [2022-09-21 08:29:12] "POST /init HTTP/1.1" 500 401 0.005821
127.0.0.1 - - [2022-09-21 08:29:14] "POST /batch_run HTTP/1.1" 200 818 1.283011
[2022-09-21 08:29:15,009] ERROR in app: Exception on /init [POST]
Traceback (most recent call last):
  File "/home/vagrant/miniconda3/lib/python3.9/site-packages/flask/app.py", line 2525, in wsgi_app
    response = self.full_dispatch_request()
  File "/home/vagrant/miniconda3/lib/python3.9/site-packages/flask/app.py", line 1822, in full_dispatch_request
    rv = self.handle_user_exception(e)
  File "/home/vagrant/miniconda3/lib/python3.9/site-packages/flask/app.py", line 1820, in full_dispatch_request
    rv = self.dispatch_request()
  File "/home/vagrant/miniconda3/lib/python3.9/site-packages/flask/app.py", line 1796, in dispatch_request
    return self.ensure_sync(self.view_functions[rule.endpoint])(**view_args)
  File "/home/vagrant/batching-request/src/azure_container/client_overhead/test/../native/proxy.py", line 70, in init
    runner.init()
  File "/home/vagrant/batching-request/src/azure_container/client_overhead/test/../native/proxy.py", line 27, in init
    with open(filename, 'r') as f:
FileNotFoundError: [Errno 2] No such file or directory: './main.py'
127.0.0.1 - - [2022-09-21 08:29:15] "POST /init HTTP/1.1" 500 401 0.005472
127.0.0.1 - - [2022-09-21 08:29:16] "POST /batch_run HTTP/1.1" 200 916 1.090346
[2022-09-21 08:29:16,823] ERROR in app: Exception on /init [POST]
Traceback (most recent call last):
  File "/home/vagrant/miniconda3/lib/python3.9/site-packages/flask/app.py", line 2525, in wsgi_app
    response = self.full_dispatch_request()
  File "/home/vagrant/miniconda3/lib/python3.9/site-packages/flask/app.py", line 1822, in full_dispatch_request
    rv = self.handle_user_exception(e)
  File "/home/vagrant/miniconda3/lib/python3.9/site-packages/flask/app.py", line 1820, in full_dispatch_request
    rv = self.dispatch_request()
  File "/home/vagrant/miniconda3/lib/python3.9/site-packages/flask/app.py", line 1796, in dispatch_request
    return self.ensure_sync(self.view_functions[rule.endpoint])(**view_args)
  File "/home/vagrant/batching-request/src/azure_container/client_overhead/test/../native/proxy.py", line 70, in init
    runner.init()
  File "/home/vagrant/batching-request/src/azure_container/client_overhead/test/../native/proxy.py", line 27, in init
    with open(filename, 'r') as f:
FileNotFoundError: [Errno 2] No such file or directory: './main.py'
127.0.0.1 - - [2022-09-21 08:29:16] "POST /init HTTP/1.1" 500 401 0.005541
127.0.0.1 - - [2022-09-21 08:29:16] "POST /batch_run HTTP/1.1" 200 189 0.071607
[2022-09-21 08:29:17,625] ERROR in app: Exception on /init [POST]
Traceback (most recent call last):
  File "/home/vagrant/miniconda3/lib/python3.9/site-packages/flask/app.py", line 2525, in wsgi_app
    response = self.full_dispatch_request()
  File "/home/vagrant/miniconda3/lib/python3.9/site-packages/flask/app.py", line 1822, in full_dispatch_request
    rv = self.handle_user_exception(e)
  File "/home/vagrant/miniconda3/lib/python3.9/site-packages/flask/app.py", line 1820, in full_dispatch_request
    rv = self.dispatch_request()
  File "/home/vagrant/miniconda3/lib/python3.9/site-packages/flask/app.py", line 1796, in dispatch_request
    return self.ensure_sync(self.view_functions[rule.endpoint])(**view_args)
  File "/home/vagrant/batching-request/src/azure_container/client_overhead/test/../native/proxy.py", line 70, in init
    runner.init()
  File "/home/vagrant/batching-request/src/azure_container/client_overhead/test/../native/proxy.py", line 27, in init
    with open(filename, 'r') as f:
FileNotFoundError: [Errno 2] No such file or directory: './main.py'
127.0.0.1 - - [2022-09-21 08:29:17] "POST /init HTTP/1.1" 500 401 0.006365
127.0.0.1 - - [2022-09-21 08:29:17] "POST /batch_run HTTP/1.1" 200 272 0.150503
[2022-09-21 08:29:18,496] ERROR in app: Exception on /init [POST]
Traceback (most recent call last):
  File "/home/vagrant/miniconda3/lib/python3.9/site-packages/flask/app.py", line 2525, in wsgi_app
    response = self.full_dispatch_request()
  File "/home/vagrant/miniconda3/lib/python3.9/site-packages/flask/app.py", line 1822, in full_dispatch_request
    rv = self.handle_user_exception(e)
  File "/home/vagrant/miniconda3/lib/python3.9/site-packages/flask/app.py", line 1820, in full_dispatch_request
    rv = self.dispatch_request()
  File "/home/vagrant/miniconda3/lib/python3.9/site-packages/flask/app.py", line 1796, in dispatch_request
    return self.ensure_sync(self.view_functions[rule.endpoint])(**view_args)
  File "/home/vagrant/batching-request/src/azure_container/client_overhead/test/../native/proxy.py", line 70, in init
    runner.init()
  File "/home/vagrant/batching-request/src/azure_container/client_overhead/test/../native/proxy.py", line 27, in init
    with open(filename, 'r') as f:
FileNotFoundError: [Errno 2] No such file or directory: './main.py'
127.0.0.1 - - [2022-09-21 08:29:18] "POST /init HTTP/1.1" 500 401 0.006084
127.0.0.1 - - [2022-09-21 08:29:18] "POST /batch_run HTTP/1.1" 200 351 0.281271
[2022-09-21 08:29:19,498] ERROR in app: Exception on /init [POST]
Traceback (most recent call last):
  File "/home/vagrant/miniconda3/lib/python3.9/site-packages/flask/app.py", line 2525, in wsgi_app
    response = self.full_dispatch_request()
  File "/home/vagrant/miniconda3/lib/python3.9/site-packages/flask/app.py", line 1822, in full_dispatch_request
    rv = self.handle_user_exception(e)
  File "/home/vagrant/miniconda3/lib/python3.9/site-packages/flask/app.py", line 1820, in full_dispatch_request
    rv = self.dispatch_request()
  File "/home/vagrant/miniconda3/lib/python3.9/site-packages/flask/app.py", line 1796, in dispatch_request
    return self.ensure_sync(self.view_functions[rule.endpoint])(**view_args)
  File "/home/vagrant/batching-request/src/azure_container/client_overhead/test/../native/proxy.py", line 70, in init
    runner.init()
  File "/home/vagrant/batching-request/src/azure_container/client_overhead/test/../native/proxy.py", line 27, in init
    with open(filename, 'r') as f:
FileNotFoundError: [Errno 2] No such file or directory: './main.py'
127.0.0.1 - - [2022-09-21 08:29:19] "POST /init HTTP/1.1" 500 401 0.005407
127.0.0.1 - - [2022-09-21 08:29:19] "POST /batch_run HTTP/1.1" 200 432 0.428986
[2022-09-21 08:29:20,644] ERROR in app: Exception on /init [POST]
Traceback (most recent call last):
  File "/home/vagrant/miniconda3/lib/python3.9/site-packages/flask/app.py", line 2525, in wsgi_app
    response = self.full_dispatch_request()
  File "/home/vagrant/miniconda3/lib/python3.9/site-packages/flask/app.py", line 1822, in full_dispatch_request
    rv = self.handle_user_exception(e)
  File "/home/vagrant/miniconda3/lib/python3.9/site-packages/flask/app.py", line 1820, in full_dispatch_request
    rv = self.dispatch_request()
  File "/home/vagrant/miniconda3/lib/python3.9/site-packages/flask/app.py", line 1796, in dispatch_request
    return self.ensure_sync(self.view_functions[rule.endpoint])(**view_args)
  File "/home/vagrant/batching-request/src/azure_container/client_overhead/test/../native/proxy.py", line 70, in init
    runner.init()
  File "/home/vagrant/batching-request/src/azure_container/client_overhead/test/../native/proxy.py", line 27, in init
    with open(filename, 'r') as f:
FileNotFoundError: [Errno 2] No such file or directory: './main.py'
127.0.0.1 - - [2022-09-21 08:29:20] "POST /init HTTP/1.1" 500 401 0.006003
127.0.0.1 - - [2022-09-21 08:29:21] "POST /batch_run HTTP/1.1" 200 509 0.815448
[2022-09-21 08:29:22,166] ERROR in app: Exception on /init [POST]
Traceback (most recent call last):
  File "/home/vagrant/miniconda3/lib/python3.9/site-packages/flask/app.py", line 2525, in wsgi_app
    response = self.full_dispatch_request()
  File "/home/vagrant/miniconda3/lib/python3.9/site-packages/flask/app.py", line 1822, in full_dispatch_request
    rv = self.handle_user_exception(e)
  File "/home/vagrant/miniconda3/lib/python3.9/site-packages/flask/app.py", line 1820, in full_dispatch_request
    rv = self.dispatch_request()
  File "/home/vagrant/miniconda3/lib/python3.9/site-packages/flask/app.py", line 1796, in dispatch_request
    return self.ensure_sync(self.view_functions[rule.endpoint])(**view_args)
  File "/home/vagrant/batching-request/src/azure_container/client_overhead/test/../native/proxy.py", line 70, in init
    runner.init()
  File "/home/vagrant/batching-request/src/azure_container/client_overhead/test/../native/proxy.py", line 27, in init
    with open(filename, 'r') as f:
FileNotFoundError: [Errno 2] No such file or directory: './main.py'
127.0.0.1 - - [2022-09-21 08:29:22] "POST /init HTTP/1.1" 500 401 0.004219
127.0.0.1 - - [2022-09-21 08:29:22] "POST /batch_run HTTP/1.1" 200 590 0.674963
[2022-09-21 08:29:23,565] ERROR in app: Exception on /init [POST]
Traceback (most recent call last):
  File "/home/vagrant/miniconda3/lib/python3.9/site-packages/flask/app.py", line 2525, in wsgi_app
    response = self.full_dispatch_request()
  File "/home/vagrant/miniconda3/lib/python3.9/site-packages/flask/app.py", line 1822, in full_dispatch_request
    rv = self.handle_user_exception(e)
  File "/home/vagrant/miniconda3/lib/python3.9/site-packages/flask/app.py", line 1820, in full_dispatch_request
    rv = self.dispatch_request()
  File "/home/vagrant/miniconda3/lib/python3.9/site-packages/flask/app.py", line 1796, in dispatch_request
    return self.ensure_sync(self.view_functions[rule.endpoint])(**view_args)
  File "/home/vagrant/batching-request/src/azure_container/client_overhead/test/../native/proxy.py", line 70, in init
    runner.init()
  File "/home/vagrant/batching-request/src/azure_container/client_overhead/test/../native/proxy.py", line 27, in init
    with open(filename, 'r') as f:
FileNotFoundError: [Errno 2] No such file or directory: './main.py'
127.0.0.1 - - [2022-09-21 08:29:23] "POST /init HTTP/1.1" 500 401 0.006020
127.0.0.1 - - [2022-09-21 08:29:24] "POST /batch_run HTTP/1.1" 200 667 0.919857
[2022-09-21 08:29:25,214] ERROR in app: Exception on /init [POST]
Traceback (most recent call last):
  File "/home/vagrant/miniconda3/lib/python3.9/site-packages/flask/app.py", line 2525, in wsgi_app
    response = self.full_dispatch_request()
  File "/home/vagrant/miniconda3/lib/python3.9/site-packages/flask/app.py", line 1822, in full_dispatch_request
    rv = self.handle_user_exception(e)
  File "/home/vagrant/miniconda3/lib/python3.9/site-packages/flask/app.py", line 1820, in full_dispatch_request
    rv = self.dispatch_request()
  File "/home/vagrant/miniconda3/lib/python3.9/site-packages/flask/app.py", line 1796, in dispatch_request
    return self.ensure_sync(self.view_functions[rule.endpoint])(**view_args)
  File "/home/vagrant/batching-request/src/azure_container/client_overhead/test/../native/proxy.py", line 70, in init
    runner.init()
  File "/home/vagrant/batching-request/src/azure_container/client_overhead/test/../native/proxy.py", line 27, in init
    with open(filename, 'r') as f:
FileNotFoundError: [Errno 2] No such file or directory: './main.py'
127.0.0.1 - - [2022-09-21 08:29:25] "POST /init HTTP/1.1" 500 401 0.005633
Traceback (most recent call last):
  File "/home/vagrant/batching-request/src/azure_container/client_overhead/test/../native/proxy.py", line 114, in <module>
    server.serve_forever()
  File "/home/vagrant/miniconda3/lib/python3.9/site-packages/gevent/baseserver.py", line 398, in serve_forever
    self.start()
  File "/home/vagrant/miniconda3/lib/python3.9/site-packages/gevent/baseserver.py", line 336, in start
    self.init_socket()
  File "/home/vagrant/miniconda3/lib/python3.9/site-packages/gevent/pywsgi.py", line 1545, in init_socket
    StreamServer.init_socket(self)
  File "/home/vagrant/miniconda3/lib/python3.9/site-packages/gevent/server.py", line 180, in init_socket
    self.socket = self.get_listener(self.address, self.backlog, self.family)
  File "/home/vagrant/miniconda3/lib/python3.9/site-packages/gevent/server.py", line 192, in get_listener
    return _tcp_listener(address, backlog=backlog, reuse_addr=cls.reuse_addr, family=family)
  File "/home/vagrant/miniconda3/lib/python3.9/site-packages/gevent/server.py", line 288, in _tcp_listener
    sock.bind(address)
  File "/home/vagrant/miniconda3/lib/python3.9/site-packages/gevent/_socketcommon.py", line 563, in bind
    return self._sock.bind(address)
OSError: [Errno 98] Address already in use: ('0.0.0.0', 5000)
[2022-09-21 08:29:32,188] ERROR in app: Exception on /init [POST]
Traceback (most recent call last):
  File "/home/vagrant/miniconda3/lib/python3.9/site-packages/flask/app.py", line 2525, in wsgi_app
    response = self.full_dispatch_request()
  File "/home/vagrant/miniconda3/lib/python3.9/site-packages/flask/app.py", line 1822, in full_dispatch_request
    rv = self.handle_user_exception(e)
  File "/home/vagrant/miniconda3/lib/python3.9/site-packages/flask/app.py", line 1820, in full_dispatch_request
    rv = self.dispatch_request()
  File "/home/vagrant/miniconda3/lib/python3.9/site-packages/flask/app.py", line 1796, in dispatch_request
    return self.ensure_sync(self.view_functions[rule.endpoint])(**view_args)
  File "/home/vagrant/batching-request/src/azure_container/client_overhead/test/../native/proxy.py", line 70, in init
    runner.init()
  File "/home/vagrant/batching-request/src/azure_container/client_overhead/test/../native/proxy.py", line 27, in init
    with open(filename, 'r') as f:
FileNotFoundError: [Errno 2] No such file or directory: './main.py'
127.0.0.1 - - [2022-09-21 08:29:32] "POST /init HTTP/1.1" 500 401 0.006042
127.0.0.1 - - [2022-09-21 08:29:32] "POST /batch_run HTTP/1.1" 200 188 0.081151
[2022-09-21 08:29:32,995] ERROR in app: Exception on /init [POST]
Traceback (most recent call last):
  File "/home/vagrant/miniconda3/lib/python3.9/site-packages/flask/app.py", line 2525, in wsgi_app
    response = self.full_dispatch_request()
  File "/home/vagrant/miniconda3/lib/python3.9/site-packages/flask/app.py", line 1822, in full_dispatch_request
    rv = self.handle_user_exception(e)
  File "/home/vagrant/miniconda3/lib/python3.9/site-packages/flask/app.py", line 1820, in full_dispatch_request
    rv = self.dispatch_request()
  File "/home/vagrant/miniconda3/lib/python3.9/site-packages/flask/app.py", line 1796, in dispatch_request
    return self.ensure_sync(self.view_functions[rule.endpoint])(**view_args)
  File "/home/vagrant/batching-request/src/azure_container/client_overhead/test/../native/proxy.py", line 70, in init
    runner.init()
  File "/home/vagrant/batching-request/src/azure_container/client_overhead/test/../native/proxy.py", line 27, in init
    with open(filename, 'r') as f:
FileNotFoundError: [Errno 2] No such file or directory: './main.py'
127.0.0.1 - - [2022-09-21 08:29:33] "POST /init HTTP/1.1" 500 401 0.006148
127.0.0.1 - - [2022-09-21 08:29:33] "POST /batch_run HTTP/1.1" 200 273 0.146009
[2022-09-21 08:29:33,857] ERROR in app: Exception on /init [POST]
Traceback (most recent call last):
  File "/home/vagrant/miniconda3/lib/python3.9/site-packages/flask/app.py", line 2525, in wsgi_app
    response = self.full_dispatch_request()
  File "/home/vagrant/miniconda3/lib/python3.9/site-packages/flask/app.py", line 1822, in full_dispatch_request
    rv = self.handle_user_exception(e)
  File "/home/vagrant/miniconda3/lib/python3.9/site-packages/flask/app.py", line 1820, in full_dispatch_request
    rv = self.dispatch_request()
  File "/home/vagrant/miniconda3/lib/python3.9/site-packages/flask/app.py", line 1796, in dispatch_request
    return self.ensure_sync(self.view_functions[rule.endpoint])(**view_args)
  File "/home/vagrant/batching-request/src/azure_container/client_overhead/test/../native/proxy.py", line 70, in init
    runner.init()
  File "/home/vagrant/batching-request/src/azure_container/client_overhead/test/../native/proxy.py", line 27, in init
    with open(filename, 'r') as f:
FileNotFoundError: [Errno 2] No such file or directory: './main.py'
127.0.0.1 - - [2022-09-21 08:29:33] "POST /init HTTP/1.1" 500 401 0.006018
127.0.0.1 - - [2022-09-21 08:29:34] "POST /batch_run HTTP/1.1" 200 348 0.292165
[2022-09-21 08:29:34,883] ERROR in app: Exception on /init [POST]
Traceback (most recent call last):
  File "/home/vagrant/miniconda3/lib/python3.9/site-packages/flask/app.py", line 2525, in wsgi_app
    response = self.full_dispatch_request()
  File "/home/vagrant/miniconda3/lib/python3.9/site-packages/flask/app.py", line 1822, in full_dispatch_request
    rv = self.handle_user_exception(e)
  File "/home/vagrant/miniconda3/lib/python3.9/site-packages/flask/app.py", line 1820, in full_dispatch_request
    rv = self.dispatch_request()
  File "/home/vagrant/miniconda3/lib/python3.9/site-packages/flask/app.py", line 1796, in dispatch_request
    return self.ensure_sync(self.view_functions[rule.endpoint])(**view_args)
  File "/home/vagrant/batching-request/src/azure_container/client_overhead/test/../native/proxy.py", line 70, in init
    runner.init()
  File "/home/vagrant/batching-request/src/azure_container/client_overhead/test/../native/proxy.py", line 27, in init
    with open(filename, 'r') as f:
FileNotFoundError: [Errno 2] No such file or directory: './main.py'
127.0.0.1 - - [2022-09-21 08:29:34] "POST /init HTTP/1.1" 500 401 0.005745
127.0.0.1 - - [2022-09-21 08:29:35] "POST /batch_run HTTP/1.1" 200 431 0.388348
[2022-09-21 08:29:36,013] ERROR in app: Exception on /init [POST]
Traceback (most recent call last):
  File "/home/vagrant/miniconda3/lib/python3.9/site-packages/flask/app.py", line 2525, in wsgi_app
    response = self.full_dispatch_request()
  File "/home/vagrant/miniconda3/lib/python3.9/site-packages/flask/app.py", line 1822, in full_dispatch_request
    rv = self.handle_user_exception(e)
  File "/home/vagrant/miniconda3/lib/python3.9/site-packages/flask/app.py", line 1820, in full_dispatch_request
    rv = self.dispatch_request()
  File "/home/vagrant/miniconda3/lib/python3.9/site-packages/flask/app.py", line 1796, in dispatch_request
    return self.ensure_sync(self.view_functions[rule.endpoint])(**view_args)
  File "/home/vagrant/batching-request/src/azure_container/client_overhead/test/../native/proxy.py", line 70, in init
    runner.init()
  File "/home/vagrant/batching-request/src/azure_container/client_overhead/test/../native/proxy.py", line 27, in init
    with open(filename, 'r') as f:
FileNotFoundError: [Errno 2] No such file or directory: './main.py'
127.0.0.1 - - [2022-09-21 08:29:36] "POST /init HTTP/1.1" 500 401 0.005861
[2022-09-21 08:29:36,881] ERROR in app: Exception on /init [POST]
Traceback (most recent call last):
  File "/home/vagrant/miniconda3/lib/python3.9/site-packages/flask/app.py", line 2525, in wsgi_app
    response = self.full_dispatch_request()
  File "/home/vagrant/miniconda3/lib/python3.9/site-packages/flask/app.py", line 1822, in full_dispatch_request
    rv = self.handle_user_exception(e)
  File "/home/vagrant/miniconda3/lib/python3.9/site-packages/flask/app.py", line 1820, in full_dispatch_request
    rv = self.dispatch_request()
  File "/home/vagrant/miniconda3/lib/python3.9/site-packages/flask/app.py", line 1796, in dispatch_request
    return self.ensure_sync(self.view_functions[rule.endpoint])(**view_args)
  File "/home/vagrant/batching-request/src/azure_container/client_overhead/test/../native/proxy.py", line 70, in init
    runner.init()
  File "/home/vagrant/batching-request/src/azure_container/client_overhead/test/../native/proxy.py", line 27, in init
    with open(filename, 'r') as f:
FileNotFoundError: [Errno 2] No such file or directory: './main.py'
127.0.0.1 - - [2022-09-21 08:29:36] "POST /init HTTP/1.1" 500 401 0.006419
Traceback (most recent call last):
  File "/home/vagrant/batching-request/src/azure_container/client_overhead/test/../native/proxy.py", line 114, in <module>
    server.serve_forever()
  File "/home/vagrant/miniconda3/lib/python3.9/site-packages/gevent/baseserver.py", line 398, in serve_forever
    self.start()
  File "/home/vagrant/miniconda3/lib/python3.9/site-packages/gevent/baseserver.py", line 336, in start
    self.init_socket()
  File "/home/vagrant/miniconda3/lib/python3.9/site-packages/gevent/pywsgi.py", line 1545, in init_socket
    StreamServer.init_socket(self)
  File "/home/vagrant/miniconda3/lib/python3.9/site-packages/gevent/server.py", line 180, in init_socket
    self.socket = self.get_listener(self.address, self.backlog, self.family)
  File "/home/vagrant/miniconda3/lib/python3.9/site-packages/gevent/server.py", line 192, in get_listener
    return _tcp_listener(address, backlog=backlog, reuse_addr=cls.reuse_addr, family=family)
  File "/home/vagrant/miniconda3/lib/python3.9/site-packages/gevent/server.py", line 288, in _tcp_listener
    sock.bind(address)
  File "/home/vagrant/miniconda3/lib/python3.9/site-packages/gevent/_socketcommon.py", line 563, in bind
    return self._sock.bind(address)
OSError: [Errno 98] Address already in use: ('0.0.0.0', 5000)
127.0.0.1 - - [2022-09-21 08:29:38] "POST /batch_run HTTP/1.1" 200 109 1.407618
[2022-09-21 08:29:38,364] ERROR in app: Exception on /init [POST]
Traceback (most recent call last):
  File "/home/vagrant/miniconda3/lib/python3.9/site-packages/flask/app.py", line 2525, in wsgi_app
    response = self.full_dispatch_request()
  File "/home/vagrant/miniconda3/lib/python3.9/site-packages/flask/app.py", line 1822, in full_dispatch_request
    rv = self.handle_user_exception(e)
  File "/home/vagrant/miniconda3/lib/python3.9/site-packages/flask/app.py", line 1820, in full_dispatch_request
    rv = self.dispatch_request()
  File "/home/vagrant/miniconda3/lib/python3.9/site-packages/flask/app.py", line 1796, in dispatch_request
    return self.ensure_sync(self.view_functions[rule.endpoint])(**view_args)
  File "/home/vagrant/batching-request/src/azure_container/client_overhead/test/../native/proxy.py", line 70, in init
    runner.init()
  File "/home/vagrant/batching-request/src/azure_container/client_overhead/test/../native/proxy.py", line 27, in init
    with open(filename, 'r') as f:
FileNotFoundError: [Errno 2] No such file or directory: './main.py'
127.0.0.1 - - [2022-09-21 08:29:38] "POST /init HTTP/1.1" 500 401 0.002699
Traceback (most recent call last):
  File "/home/vagrant/batching-request/src/azure_container/client_overhead/test/../native/proxy.py", line 114, in <module>
    server.serve_forever()
  File "/home/vagrant/miniconda3/lib/python3.9/site-packages/gevent/baseserver.py", line 398, in serve_forever
    self.start()
  File "/home/vagrant/miniconda3/lib/python3.9/site-packages/gevent/baseserver.py", line 336, in start
    self.init_socket()
  File "/home/vagrant/miniconda3/lib/python3.9/site-packages/gevent/pywsgi.py", line 1545, in init_socket
    StreamServer.init_socket(self)
  File "/home/vagrant/miniconda3/lib/python3.9/site-packages/gevent/server.py", line 180, in init_socket
    self.socket = self.get_listener(self.address, self.backlog, self.family)
  File "/home/vagrant/miniconda3/lib/python3.9/site-packages/gevent/server.py", line 192, in get_listener
    return _tcp_listener(address, backlog=backlog, reuse_addr=cls.reuse_addr, family=family)
  File "/home/vagrant/miniconda3/lib/python3.9/site-packages/gevent/server.py", line 288, in _tcp_listener
    sock.bind(address)
  File "/home/vagrant/miniconda3/lib/python3.9/site-packages/gevent/_socketcommon.py", line 563, in bind
    return self._sock.bind(address)
OSError: [Errno 98] Address already in use: ('0.0.0.0', 5000)
Traceback (most recent call last):
  File "/home/vagrant/batching-request/src/azure_container/client_overhead/test/../native/proxy.py", line 114, in <module>
    server.serve_forever()
  File "/home/vagrant/miniconda3/lib/python3.9/site-packages/gevent/baseserver.py", line 398, in serve_forever
    self.start()
  File "/home/vagrant/miniconda3/lib/python3.9/site-packages/gevent/baseserver.py", line 336, in start
    self.init_socket()
  File "/home/vagrant/miniconda3/lib/python3.9/site-packages/gevent/pywsgi.py", line 1545, in init_socket
    StreamServer.init_socket(self)
  File "/home/vagrant/miniconda3/lib/python3.9/site-packages/gevent/server.py", line 180, in init_socket
    self.socket = self.get_listener(self.address, self.backlog, self.family)
  File "/home/vagrant/miniconda3/lib/python3.9/site-packages/gevent/server.py", line 192, in get_listener
    return _tcp_listener(address, backlog=backlog, reuse_addr=cls.reuse_addr, family=family)
  File "/home/vagrant/miniconda3/lib/python3.9/site-packages/gevent/server.py", line 288, in _tcp_listener
    sock.bind(address)
  File "/home/vagrant/miniconda3/lib/python3.9/site-packages/gevent/_socketcommon.py", line 563, in bind
    return self._sock.bind(address)
OSError: [Errno 98] Address already in use: ('0.0.0.0', 5000)
[2022-09-21 08:32:48,395] ERROR in app: Exception on /init [POST]
Traceback (most recent call last):
  File "/home/vagrant/miniconda3/lib/python3.9/site-packages/flask/app.py", line 2525, in wsgi_app
    response = self.full_dispatch_request()
  File "/home/vagrant/miniconda3/lib/python3.9/site-packages/flask/app.py", line 1822, in full_dispatch_request
    rv = self.handle_user_exception(e)
  File "/home/vagrant/miniconda3/lib/python3.9/site-packages/flask/app.py", line 1820, in full_dispatch_request
    rv = self.dispatch_request()
  File "/home/vagrant/miniconda3/lib/python3.9/site-packages/flask/app.py", line 1796, in dispatch_request
    return self.ensure_sync(self.view_functions[rule.endpoint])(**view_args)
  File "/home/vagrant/batching-request/src/azure_container/client_overhead/test/../native/proxy.py", line 70, in init
    runner.init()
  File "/home/vagrant/batching-request/src/azure_container/client_overhead/test/../native/proxy.py", line 27, in init
    with open(filename, 'r') as f:
FileNotFoundError: [Errno 2] No such file or directory: './main.py'
127.0.0.1 - - [2022-09-21 08:32:48] "POST /init HTTP/1.1" 500 401 0.002366
127.0.0.1 - - [2022-09-21 08:32:48] "POST /batch_run HTTP/1.1" 200 184 0.073925
[2022-09-21 08:32:49,181] ERROR in app: Exception on /init [POST]
Traceback (most recent call last):
  File "/home/vagrant/miniconda3/lib/python3.9/site-packages/flask/app.py", line 2525, in wsgi_app
    response = self.full_dispatch_request()
  File "/home/vagrant/miniconda3/lib/python3.9/site-packages/flask/app.py", line 1822, in full_dispatch_request
    rv = self.handle_user_exception(e)
  File "/home/vagrant/miniconda3/lib/python3.9/site-packages/flask/app.py", line 1820, in full_dispatch_request
    rv = self.dispatch_request()
  File "/home/vagrant/miniconda3/lib/python3.9/site-packages/flask/app.py", line 1796, in dispatch_request
    return self.ensure_sync(self.view_functions[rule.endpoint])(**view_args)
  File "/home/vagrant/batching-request/src/azure_container/client_overhead/test/../native/proxy.py", line 70, in init
    runner.init()
  File "/home/vagrant/batching-request/src/azure_container/client_overhead/test/../native/proxy.py", line 27, in init
    with open(filename, 'r') as f:
FileNotFoundError: [Errno 2] No such file or directory: './main.py'
127.0.0.1 - - [2022-09-21 08:32:49] "POST /init HTTP/1.1" 500 401 0.005480
[2022-09-21 08:32:49,959] ERROR in app: Exception on /init [POST]
Traceback (most recent call last):
  File "/home/vagrant/miniconda3/lib/python3.9/site-packages/flask/app.py", line 2525, in wsgi_app
    response = self.full_dispatch_request()
  File "/home/vagrant/miniconda3/lib/python3.9/site-packages/flask/app.py", line 1822, in full_dispatch_request
    rv = self.handle_user_exception(e)
  File "/home/vagrant/miniconda3/lib/python3.9/site-packages/flask/app.py", line 1820, in full_dispatch_request
    rv = self.dispatch_request()
  File "/home/vagrant/miniconda3/lib/python3.9/site-packages/flask/app.py", line 1796, in dispatch_request
    return self.ensure_sync(self.view_functions[rule.endpoint])(**view_args)
  File "/home/vagrant/batching-request/src/azure_container/client_overhead/test/../native/proxy.py", line 70, in init
    runner.init()
  File "/home/vagrant/batching-request/src/azure_container/client_overhead/test/../native/proxy.py", line 27, in init
    with open(filename, 'r') as f:
FileNotFoundError: [Errno 2] No such file or directory: './main.py'
127.0.0.1 - - [2022-09-21 08:32:49] "POST /init HTTP/1.1" 500 401 0.005392
Traceback (most recent call last):
  File "/home/vagrant/batching-request/src/azure_container/client_overhead/test/../native/proxy.py", line 114, in <module>
    server.serve_forever()
  File "/home/vagrant/miniconda3/lib/python3.9/site-packages/gevent/baseserver.py", line 398, in serve_forever
    self.start()
  File "/home/vagrant/miniconda3/lib/python3.9/site-packages/gevent/baseserver.py", line 336, in start
    self.init_socket()
  File "/home/vagrant/miniconda3/lib/python3.9/site-packages/gevent/pywsgi.py", line 1545, in init_socket
    StreamServer.init_socket(self)
  File "/home/vagrant/miniconda3/lib/python3.9/site-packages/gevent/server.py", line 180, in init_socket
    self.socket = self.get_listener(self.address, self.backlog, self.family)
  File "/home/vagrant/miniconda3/lib/python3.9/site-packages/gevent/server.py", line 192, in get_listener
    return _tcp_listener(address, backlog=backlog, reuse_addr=cls.reuse_addr, family=family)
  File "/home/vagrant/miniconda3/lib/python3.9/site-packages/gevent/server.py", line 288, in _tcp_listener
    sock.bind(address)
  File "/home/vagrant/miniconda3/lib/python3.9/site-packages/gevent/_socketcommon.py", line 563, in bind
    return self._sock.bind(address)
OSError: [Errno 98] Address already in use: ('0.0.0.0', 5000)
Traceback (most recent call last):
  File "/home/vagrant/batching-request/src/azure_container/client_overhead/test/../native/proxy.py", line 114, in <module>
    server.serve_forever()
  File "/home/vagrant/miniconda3/lib/python3.9/site-packages/gevent/baseserver.py", line 398, in serve_forever
    self.start()
  File "/home/vagrant/miniconda3/lib/python3.9/site-packages/gevent/baseserver.py", line 336, in start
    self.init_socket()
  File "/home/vagrant/miniconda3/lib/python3.9/site-packages/gevent/pywsgi.py", line 1545, in init_socket
    StreamServer.init_socket(self)
  File "/home/vagrant/miniconda3/lib/python3.9/site-packages/gevent/server.py", line 180, in init_socket
    self.socket = self.get_listener(self.address, self.backlog, self.family)
  File "/home/vagrant/miniconda3/lib/python3.9/site-packages/gevent/server.py", line 192, in get_listener
    return _tcp_listener(address, backlog=backlog, reuse_addr=cls.reuse_addr, family=family)
  File "/home/vagrant/miniconda3/lib/python3.9/site-packages/gevent/server.py", line 288, in _tcp_listener
    sock.bind(address)
  File "/home/vagrant/miniconda3/lib/python3.9/site-packages/gevent/_socketcommon.py", line 563, in bind
    return self._sock.bind(address)
OSError: [Errno 98] Address already in use: ('0.0.0.0', 5000)
[2022-09-21 08:33:29,319] ERROR in app: Exception on /init [POST]
Traceback (most recent call last):
  File "/home/vagrant/miniconda3/lib/python3.9/site-packages/flask/app.py", line 2525, in wsgi_app
    response = self.full_dispatch_request()
  File "/home/vagrant/miniconda3/lib/python3.9/site-packages/flask/app.py", line 1822, in full_dispatch_request
    rv = self.handle_user_exception(e)
  File "/home/vagrant/miniconda3/lib/python3.9/site-packages/flask/app.py", line 1820, in full_dispatch_request
    rv = self.dispatch_request()
  File "/home/vagrant/miniconda3/lib/python3.9/site-packages/flask/app.py", line 1796, in dispatch_request
    return self.ensure_sync(self.view_functions[rule.endpoint])(**view_args)
  File "/home/vagrant/batching-request/src/azure_container/client_overhead/test/../native/proxy.py", line 70, in init
    runner.init()
  File "/home/vagrant/batching-request/src/azure_container/client_overhead/test/../native/proxy.py", line 27, in init
    with open(filename, 'r') as f:
FileNotFoundError: [Errno 2] No such file or directory: './main.py'
127.0.0.1 - - [2022-09-21 08:33:29] "POST /init HTTP/1.1" 500 401 0.005670
127.0.0.1 - - [2022-09-21 08:33:29] "POST /batch_run HTTP/1.1" 200 189 0.075089
[2022-09-21 08:33:30,114] ERROR in app: Exception on /init [POST]
Traceback (most recent call last):
  File "/home/vagrant/miniconda3/lib/python3.9/site-packages/flask/app.py", line 2525, in wsgi_app
    response = self.full_dispatch_request()
  File "/home/vagrant/miniconda3/lib/python3.9/site-packages/flask/app.py", line 1822, in full_dispatch_request
    rv = self.handle_user_exception(e)
  File "/home/vagrant/miniconda3/lib/python3.9/site-packages/flask/app.py", line 1820, in full_dispatch_request
    rv = self.dispatch_request()
  File "/home/vagrant/miniconda3/lib/python3.9/site-packages/flask/app.py", line 1796, in dispatch_request
    return self.ensure_sync(self.view_functions[rule.endpoint])(**view_args)
  File "/home/vagrant/batching-request/src/azure_container/client_overhead/test/../native/proxy.py", line 70, in init
    runner.init()
  File "/home/vagrant/batching-request/src/azure_container/client_overhead/test/../native/proxy.py", line 27, in init
    with open(filename, 'r') as f:
FileNotFoundError: [Errno 2] No such file or directory: './main.py'
127.0.0.1 - - [2022-09-21 08:33:30] "POST /init HTTP/1.1" 500 401 0.005858
127.0.0.1 - - [2022-09-21 08:33:30] "POST /batch_run HTTP/1.1" 200 273 0.168446
[2022-09-21 08:33:31,013] ERROR in app: Exception on /init [POST]
Traceback (most recent call last):
  File "/home/vagrant/miniconda3/lib/python3.9/site-packages/flask/app.py", line 2525, in wsgi_app
    response = self.full_dispatch_request()
  File "/home/vagrant/miniconda3/lib/python3.9/site-packages/flask/app.py", line 1822, in full_dispatch_request
    rv = self.handle_user_exception(e)
  File "/home/vagrant/miniconda3/lib/python3.9/site-packages/flask/app.py", line 1820, in full_dispatch_request
    rv = self.dispatch_request()
  File "/home/vagrant/miniconda3/lib/python3.9/site-packages/flask/app.py", line 1796, in dispatch_request
    return self.ensure_sync(self.view_functions[rule.endpoint])(**view_args)
  File "/home/vagrant/batching-request/src/azure_container/client_overhead/test/../native/proxy.py", line 70, in init
    runner.init()
  File "/home/vagrant/batching-request/src/azure_container/client_overhead/test/../native/proxy.py", line 27, in init
    with open(filename, 'r') as f:
FileNotFoundError: [Errno 2] No such file or directory: './main.py'
127.0.0.1 - - [2022-09-21 08:33:31] "POST /init HTTP/1.1" 500 401 0.005763
127.0.0.1 - - [2022-09-21 08:33:31] "POST /batch_run HTTP/1.1" 200 347 0.319864
[2022-09-21 08:33:32,082] ERROR in app: Exception on /init [POST]
Traceback (most recent call last):
  File "/home/vagrant/miniconda3/lib/python3.9/site-packages/flask/app.py", line 2525, in wsgi_app
    response = self.full_dispatch_request()
  File "/home/vagrant/miniconda3/lib/python3.9/site-packages/flask/app.py", line 1822, in full_dispatch_request
    rv = self.handle_user_exception(e)
  File "/home/vagrant/miniconda3/lib/python3.9/site-packages/flask/app.py", line 1820, in full_dispatch_request
    rv = self.dispatch_request()
  File "/home/vagrant/miniconda3/lib/python3.9/site-packages/flask/app.py", line 1796, in dispatch_request
    return self.ensure_sync(self.view_functions[rule.endpoint])(**view_args)
  File "/home/vagrant/batching-request/src/azure_container/client_overhead/test/../native/proxy.py", line 70, in init
    runner.init()
  File "/home/vagrant/batching-request/src/azure_container/client_overhead/test/../native/proxy.py", line 27, in init
    with open(filename, 'r') as f:
FileNotFoundError: [Errno 2] No such file or directory: './main.py'
127.0.0.1 - - [2022-09-21 08:33:32] "POST /init HTTP/1.1" 500 401 0.005574
127.0.0.1 - - [2022-09-21 08:33:33] "POST /batch_run HTTP/1.1" 200 431 1.706735
[2022-09-21 08:33:34,504] ERROR in app: Exception on /init [POST]
Traceback (most recent call last):
  File "/home/vagrant/miniconda3/lib/python3.9/site-packages/flask/app.py", line 2525, in wsgi_app
    response = self.full_dispatch_request()
  File "/home/vagrant/miniconda3/lib/python3.9/site-packages/flask/app.py", line 1822, in full_dispatch_request
    rv = self.handle_user_exception(e)
  File "/home/vagrant/miniconda3/lib/python3.9/site-packages/flask/app.py", line 1820, in full_dispatch_request
    rv = self.dispatch_request()
  File "/home/vagrant/miniconda3/lib/python3.9/site-packages/flask/app.py", line 1796, in dispatch_request
    return self.ensure_sync(self.view_functions[rule.endpoint])(**view_args)
  File "/home/vagrant/batching-request/src/azure_container/client_overhead/test/../native/proxy.py", line 70, in init
    runner.init()
  File "/home/vagrant/batching-request/src/azure_container/client_overhead/test/../native/proxy.py", line 27, in init
    with open(filename, 'r') as f:
FileNotFoundError: [Errno 2] No such file or directory: './main.py'
127.0.0.1 - - [2022-09-21 08:33:34] "POST /init HTTP/1.1" 500 401 0.006072
127.0.0.1 - - [2022-09-21 08:33:35] "POST /batch_run HTTP/1.1" 200 508 0.776358
[2022-09-21 08:33:36,011] ERROR in app: Exception on /init [POST]
Traceback (most recent call last):
  File "/home/vagrant/miniconda3/lib/python3.9/site-packages/flask/app.py", line 2525, in wsgi_app
    response = self.full_dispatch_request()
  File "/home/vagrant/miniconda3/lib/python3.9/site-packages/flask/app.py", line 1822, in full_dispatch_request
    rv = self.handle_user_exception(e)
  File "/home/vagrant/miniconda3/lib/python3.9/site-packages/flask/app.py", line 1820, in full_dispatch_request
    rv = self.dispatch_request()
  File "/home/vagrant/miniconda3/lib/python3.9/site-packages/flask/app.py", line 1796, in dispatch_request
    return self.ensure_sync(self.view_functions[rule.endpoint])(**view_args)
  File "/home/vagrant/batching-request/src/azure_container/client_overhead/test/../native/proxy.py", line 70, in init
    runner.init()
  File "/home/vagrant/batching-request/src/azure_container/client_overhead/test/../native/proxy.py", line 27, in init
    with open(filename, 'r') as f:
FileNotFoundError: [Errno 2] No such file or directory: './main.py'
127.0.0.1 - - [2022-09-21 08:33:36] "POST /init HTTP/1.1" 500 401 0.005209
[2022-09-21 08:33:37,417] ERROR in app: Exception on /init [POST]
Traceback (most recent call last):
  File "/home/vagrant/miniconda3/lib/python3.9/site-packages/flask/app.py", line 2525, in wsgi_app
    response = self.full_dispatch_request()
  File "/home/vagrant/miniconda3/lib/python3.9/site-packages/flask/app.py", line 1822, in full_dispatch_request
    rv = self.handle_user_exception(e)
  File "/home/vagrant/miniconda3/lib/python3.9/site-packages/flask/app.py", line 1820, in full_dispatch_request
    rv = self.dispatch_request()
  File "/home/vagrant/miniconda3/lib/python3.9/site-packages/flask/app.py", line 1796, in dispatch_request
    return self.ensure_sync(self.view_functions[rule.endpoint])(**view_args)
  File "/home/vagrant/batching-request/src/azure_container/client_overhead/test/../native/proxy.py", line 70, in init
    runner.init()
  File "/home/vagrant/batching-request/src/azure_container/client_overhead/test/../native/proxy.py", line 27, in init
    with open(filename, 'r') as f:
FileNotFoundError: [Errno 2] No such file or directory: './main.py'
127.0.0.1 - - [2022-09-21 08:33:37] "POST /init HTTP/1.1" 500 136 0.005598
Traceback (most recent call last):
  File "/home/vagrant/batching-request/src/azure_container/client_overhead/test/../native/proxy.py", line 114, in <module>
    server.serve_forever()
  File "/home/vagrant/miniconda3/lib/python3.9/site-packages/gevent/baseserver.py", line 398, in serve_forever
    self.start()
  File "/home/vagrant/miniconda3/lib/python3.9/site-packages/gevent/baseserver.py", line 336, in start
    self.init_socket()
  File "/home/vagrant/miniconda3/lib/python3.9/site-packages/gevent/pywsgi.py", line 1545, in init_socket
    StreamServer.init_socket(self)
  File "/home/vagrant/miniconda3/lib/python3.9/site-packages/gevent/server.py", line 180, in init_socket
    self.socket = self.get_listener(self.address, self.backlog, self.family)
  File "/home/vagrant/miniconda3/lib/python3.9/site-packages/gevent/server.py", line 192, in get_listener
    return _tcp_listener(address, backlog=backlog, reuse_addr=cls.reuse_addr, family=family)
  File "/home/vagrant/miniconda3/lib/python3.9/site-packages/gevent/server.py", line 288, in _tcp_listener
    sock.bind(address)
  File "/home/vagrant/miniconda3/lib/python3.9/site-packages/gevent/_socketcommon.py", line 563, in bind
    return self._sock.bind(address)
OSError: [Errno 98] Address already in use: ('0.0.0.0', 5000)
[2022-09-21 08:33:44,423] ERROR in app: Exception on /init [POST]
Traceback (most recent call last):
  File "/home/vagrant/miniconda3/lib/python3.9/site-packages/flask/app.py", line 2525, in wsgi_app
    response = self.full_dispatch_request()
  File "/home/vagrant/miniconda3/lib/python3.9/site-packages/flask/app.py", line 1822, in full_dispatch_request
    rv = self.handle_user_exception(e)
  File "/home/vagrant/miniconda3/lib/python3.9/site-packages/flask/app.py", line 1820, in full_dispatch_request
    rv = self.dispatch_request()
  File "/home/vagrant/miniconda3/lib/python3.9/site-packages/flask/app.py", line 1796, in dispatch_request
    return self.ensure_sync(self.view_functions[rule.endpoint])(**view_args)
  File "/home/vagrant/batching-request/src/azure_container/client_overhead/test/../native/proxy.py", line 70, in init
    runner.init()
  File "/home/vagrant/batching-request/src/azure_container/client_overhead/test/../native/proxy.py", line 27, in init
    with open(filename, 'r') as f:
FileNotFoundError: [Errno 2] No such file or directory: './main.py'
127.0.0.1 - - [2022-09-21 08:33:44] "POST /init HTTP/1.1" 500 401 0.005483
127.0.0.1 - - [2022-09-21 08:33:44] "POST /batch_run HTTP/1.1" 200 184 0.082775
[2022-09-21 08:33:45,245] ERROR in app: Exception on /init [POST]
Traceback (most recent call last):
  File "/home/vagrant/miniconda3/lib/python3.9/site-packages/flask/app.py", line 2525, in wsgi_app
    response = self.full_dispatch_request()
  File "/home/vagrant/miniconda3/lib/python3.9/site-packages/flask/app.py", line 1822, in full_dispatch_request
    rv = self.handle_user_exception(e)
  File "/home/vagrant/miniconda3/lib/python3.9/site-packages/flask/app.py", line 1820, in full_dispatch_request
    rv = self.dispatch_request()
  File "/home/vagrant/miniconda3/lib/python3.9/site-packages/flask/app.py", line 1796, in dispatch_request
    return self.ensure_sync(self.view_functions[rule.endpoint])(**view_args)
  File "/home/vagrant/batching-request/src/azure_container/client_overhead/test/../native/proxy.py", line 70, in init
    runner.init()
  File "/home/vagrant/batching-request/src/azure_container/client_overhead/test/../native/proxy.py", line 27, in init
    with open(filename, 'r') as f:
FileNotFoundError: [Errno 2] No such file or directory: './main.py'
127.0.0.1 - - [2022-09-21 08:33:45] "POST /init HTTP/1.1" 500 401 0.005985
127.0.0.1 - - [2022-09-21 08:33:45] "POST /batch_run HTTP/1.1" 200 269 0.604424
[2022-09-21 08:33:46,580] ERROR in app: Exception on /init [POST]
Traceback (most recent call last):
  File "/home/vagrant/miniconda3/lib/python3.9/site-packages/flask/app.py", line 2525, in wsgi_app
    response = self.full_dispatch_request()
  File "/home/vagrant/miniconda3/lib/python3.9/site-packages/flask/app.py", line 1822, in full_dispatch_request
    rv = self.handle_user_exception(e)
  File "/home/vagrant/miniconda3/lib/python3.9/site-packages/flask/app.py", line 1820, in full_dispatch_request
    rv = self.dispatch_request()
  File "/home/vagrant/miniconda3/lib/python3.9/site-packages/flask/app.py", line 1796, in dispatch_request
    return self.ensure_sync(self.view_functions[rule.endpoint])(**view_args)
  File "/home/vagrant/batching-request/src/azure_container/client_overhead/test/../native/proxy.py", line 70, in init
    runner.init()
  File "/home/vagrant/batching-request/src/azure_container/client_overhead/test/../native/proxy.py", line 27, in init
    with open(filename, 'r') as f:
FileNotFoundError: [Errno 2] No such file or directory: './main.py'
127.0.0.1 - - [2022-09-21 08:33:46] "POST /init HTTP/1.1" 500 401 0.005631
127.0.0.1 - - [2022-09-21 08:33:47] "POST /batch_run HTTP/1.1" 200 348 0.772898
[2022-09-21 08:33:48,083] ERROR in app: Exception on /init [POST]
Traceback (most recent call last):
  File "/home/vagrant/miniconda3/lib/python3.9/site-packages/flask/app.py", line 2525, in wsgi_app
    response = self.full_dispatch_request()
  File "/home/vagrant/miniconda3/lib/python3.9/site-packages/flask/app.py", line 1822, in full_dispatch_request
    rv = self.handle_user_exception(e)
  File "/home/vagrant/miniconda3/lib/python3.9/site-packages/flask/app.py", line 1820, in full_dispatch_request
    rv = self.dispatch_request()
  File "/home/vagrant/miniconda3/lib/python3.9/site-packages/flask/app.py", line 1796, in dispatch_request
    return self.ensure_sync(self.view_functions[rule.endpoint])(**view_args)
  File "/home/vagrant/batching-request/src/azure_container/client_overhead/test/../native/proxy.py", line 70, in init
    runner.init()
  File "/home/vagrant/batching-request/src/azure_container/client_overhead/test/../native/proxy.py", line 27, in init
    with open(filename, 'r') as f:
FileNotFoundError: [Errno 2] No such file or directory: './main.py'
127.0.0.1 - - [2022-09-21 08:33:48] "POST /init HTTP/1.1" 500 401 0.006043
127.0.0.1 - - [2022-09-21 08:33:49] "POST /batch_run HTTP/1.1" 200 431 1.786579
[2022-09-21 08:33:50,594] ERROR in app: Exception on /init [POST]
Traceback (most recent call last):
  File "/home/vagrant/miniconda3/lib/python3.9/site-packages/flask/app.py", line 2525, in wsgi_app
    response = self.full_dispatch_request()
  File "/home/vagrant/miniconda3/lib/python3.9/site-packages/flask/app.py", line 1822, in full_dispatch_request
    rv = self.handle_user_exception(e)
  File "/home/vagrant/miniconda3/lib/python3.9/site-packages/flask/app.py", line 1820, in full_dispatch_request
    rv = self.dispatch_request()
  File "/home/vagrant/miniconda3/lib/python3.9/site-packages/flask/app.py", line 1796, in dispatch_request
    return self.ensure_sync(self.view_functions[rule.endpoint])(**view_args)
  File "/home/vagrant/batching-request/src/azure_container/client_overhead/test/../native/proxy.py", line 70, in init
    runner.init()
  File "/home/vagrant/batching-request/src/azure_container/client_overhead/test/../native/proxy.py", line 27, in init
    with open(filename, 'r') as f:
FileNotFoundError: [Errno 2] No such file or directory: './main.py'
127.0.0.1 - - [2022-09-21 08:33:50] "POST /init HTTP/1.1" 500 401 0.005847
127.0.0.1 - - [2022-09-21 08:33:51] "POST /batch_run HTTP/1.1" 200 503 0.831469
[2022-09-21 08:33:52,159] ERROR in app: Exception on /init [POST]
Traceback (most recent call last):
  File "/home/vagrant/miniconda3/lib/python3.9/site-packages/flask/app.py", line 2525, in wsgi_app
    response = self.full_dispatch_request()
  File "/home/vagrant/miniconda3/lib/python3.9/site-packages/flask/app.py", line 1822, in full_dispatch_request
    rv = self.handle_user_exception(e)
  File "/home/vagrant/miniconda3/lib/python3.9/site-packages/flask/app.py", line 1820, in full_dispatch_request
    rv = self.dispatch_request()
  File "/home/vagrant/miniconda3/lib/python3.9/site-packages/flask/app.py", line 1796, in dispatch_request
    return self.ensure_sync(self.view_functions[rule.endpoint])(**view_args)
  File "/home/vagrant/batching-request/src/azure_container/client_overhead/test/../native/proxy.py", line 70, in init
    runner.init()
  File "/home/vagrant/batching-request/src/azure_container/client_overhead/test/../native/proxy.py", line 27, in init
    with open(filename, 'r') as f:
FileNotFoundError: [Errno 2] No such file or directory: './main.py'
127.0.0.1 - - [2022-09-21 08:33:52] "POST /init HTTP/1.1" 500 401 0.005584
127.0.0.1 - - [2022-09-21 08:33:54] "POST /batch_run HTTP/1.1" 200 588 2.524877
[2022-09-21 08:33:55,415] ERROR in app: Exception on /init [POST]
Traceback (most recent call last):
  File "/home/vagrant/miniconda3/lib/python3.9/site-packages/flask/app.py", line 2525, in wsgi_app
    response = self.full_dispatch_request()
  File "/home/vagrant/miniconda3/lib/python3.9/site-packages/flask/app.py", line 1822, in full_dispatch_request
    rv = self.handle_user_exception(e)
  File "/home/vagrant/miniconda3/lib/python3.9/site-packages/flask/app.py", line 1820, in full_dispatch_request
    rv = self.dispatch_request()
  File "/home/vagrant/miniconda3/lib/python3.9/site-packages/flask/app.py", line 1796, in dispatch_request
    return self.ensure_sync(self.view_functions[rule.endpoint])(**view_args)
  File "/home/vagrant/batching-request/src/azure_container/client_overhead/test/../native/proxy.py", line 70, in init
    runner.init()
  File "/home/vagrant/batching-request/src/azure_container/client_overhead/test/../native/proxy.py", line 27, in init
    with open(filename, 'r') as f:
FileNotFoundError: [Errno 2] No such file or directory: './main.py'
127.0.0.1 - - [2022-09-21 08:33:55] "POST /init HTTP/1.1" 500 401 0.006014
127.0.0.1 - - [2022-09-21 08:33:56] "POST /batch_run HTTP/1.1" 200 661 0.703427
[2022-09-21 08:33:56,839] ERROR in app: Exception on /init [POST]
Traceback (most recent call last):
  File "/home/vagrant/miniconda3/lib/python3.9/site-packages/flask/app.py", line 2525, in wsgi_app
    response = self.full_dispatch_request()
  File "/home/vagrant/miniconda3/lib/python3.9/site-packages/flask/app.py", line 1822, in full_dispatch_request
    rv = self.handle_user_exception(e)
  File "/home/vagrant/miniconda3/lib/python3.9/site-packages/flask/app.py", line 1820, in full_dispatch_request
    rv = self.dispatch_request()
  File "/home/vagrant/miniconda3/lib/python3.9/site-packages/flask/app.py", line 1796, in dispatch_request
    return self.ensure_sync(self.view_functions[rule.endpoint])(**view_args)
  File "/home/vagrant/batching-request/src/azure_container/client_overhead/test/../native/proxy.py", line 70, in init
    runner.init()
  File "/home/vagrant/batching-request/src/azure_container/client_overhead/test/../native/proxy.py", line 27, in init
    with open(filename, 'r') as f:
FileNotFoundError: [Errno 2] No such file or directory: './main.py'
127.0.0.1 - - [2022-09-21 08:33:56] "POST /init HTTP/1.1" 500 401 0.005877
127.0.0.1 - - [2022-09-21 08:33:57] "POST /batch_run HTTP/1.1" 200 739 1.012648
[2022-09-21 08:33:58,594] ERROR in app: Exception on /init [POST]
Traceback (most recent call last):
  File "/home/vagrant/miniconda3/lib/python3.9/site-packages/flask/app.py", line 2525, in wsgi_app
    response = self.full_dispatch_request()
  File "/home/vagrant/miniconda3/lib/python3.9/site-packages/flask/app.py", line 1822, in full_dispatch_request
    rv = self.handle_user_exception(e)
  File "/home/vagrant/miniconda3/lib/python3.9/site-packages/flask/app.py", line 1820, in full_dispatch_request
    rv = self.dispatch_request()
  File "/home/vagrant/miniconda3/lib/python3.9/site-packages/flask/app.py", line 1796, in dispatch_request
    return self.ensure_sync(self.view_functions[rule.endpoint])(**view_args)
  File "/home/vagrant/batching-request/src/azure_container/client_overhead/test/../native/proxy.py", line 70, in init
    runner.init()
  File "/home/vagrant/batching-request/src/azure_container/client_overhead/test/../native/proxy.py", line 27, in init
    with open(filename, 'r') as f:
FileNotFoundError: [Errno 2] No such file or directory: './main.py'
127.0.0.1 - - [2022-09-21 08:33:58] "POST /init HTTP/1.1" 500 401 0.005810
127.0.0.1 - - [2022-09-21 08:33:59] "POST /batch_run HTTP/1.1" 200 821 1.118897
[2022-09-21 08:34:00,427] ERROR in app: Exception on /init [POST]
Traceback (most recent call last):
  File "/home/vagrant/miniconda3/lib/python3.9/site-packages/flask/app.py", line 2525, in wsgi_app
    response = self.full_dispatch_request()
  File "/home/vagrant/miniconda3/lib/python3.9/site-packages/flask/app.py", line 1822, in full_dispatch_request
    rv = self.handle_user_exception(e)
  File "/home/vagrant/miniconda3/lib/python3.9/site-packages/flask/app.py", line 1820, in full_dispatch_request
    rv = self.dispatch_request()
  File "/home/vagrant/miniconda3/lib/python3.9/site-packages/flask/app.py", line 1796, in dispatch_request
    return self.ensure_sync(self.view_functions[rule.endpoint])(**view_args)
  File "/home/vagrant/batching-request/src/azure_container/client_overhead/test/../native/proxy.py", line 70, in init
    runner.init()
  File "/home/vagrant/batching-request/src/azure_container/client_overhead/test/../native/proxy.py", line 27, in init
    with open(filename, 'r') as f:
FileNotFoundError: [Errno 2] No such file or directory: './main.py'
127.0.0.1 - - [2022-09-21 08:34:00] "POST /init HTTP/1.1" 500 401 0.005888
127.0.0.1 - - [2022-09-21 08:34:04] "POST /batch_run HTTP/1.1" 200 925 3.652343
[2022-09-21 08:34:29,263] ERROR in app: Exception on /init [POST]
Traceback (most recent call last):
  File "/home/vagrant/miniconda3/lib/python3.9/site-packages/flask/app.py", line 2525, in wsgi_app
    response = self.full_dispatch_request()
  File "/home/vagrant/miniconda3/lib/python3.9/site-packages/flask/app.py", line 1822, in full_dispatch_request
    rv = self.handle_user_exception(e)
  File "/home/vagrant/miniconda3/lib/python3.9/site-packages/flask/app.py", line 1820, in full_dispatch_request
    rv = self.dispatch_request()
  File "/home/vagrant/miniconda3/lib/python3.9/site-packages/flask/app.py", line 1796, in dispatch_request
    return self.ensure_sync(self.view_functions[rule.endpoint])(**view_args)
  File "/home/vagrant/batching-request/src/azure_container/client_overhead/test/../optimize/proxy.py", line 103, in init
    runner.init()
  File "/home/vagrant/batching-request/src/azure_container/client_overhead/test/../optimize/proxy.py", line 30, in init
    with open(filename, 'r') as f:
FileNotFoundError: [Errno 2] No such file or directory: './main.py'
127.0.0.1 - - [2022-09-21 08:34:29] "POST /init HTTP/1.1" 500 401 0.005652
127.0.0.1 - - [2022-09-21 08:34:29] "POST /batch_run HTTP/1.1" 200 188 0.053429
[2022-09-21 08:34:30,028] ERROR in app: Exception on /init [POST]
Traceback (most recent call last):
  File "/home/vagrant/miniconda3/lib/python3.9/site-packages/flask/app.py", line 2525, in wsgi_app
    response = self.full_dispatch_request()
  File "/home/vagrant/miniconda3/lib/python3.9/site-packages/flask/app.py", line 1822, in full_dispatch_request
    rv = self.handle_user_exception(e)
  File "/home/vagrant/miniconda3/lib/python3.9/site-packages/flask/app.py", line 1820, in full_dispatch_request
    rv = self.dispatch_request()
  File "/home/vagrant/miniconda3/lib/python3.9/site-packages/flask/app.py", line 1796, in dispatch_request
    return self.ensure_sync(self.view_functions[rule.endpoint])(**view_args)
  File "/home/vagrant/batching-request/src/azure_container/client_overhead/test/../optimize/proxy.py", line 103, in init
    runner.init()
  File "/home/vagrant/batching-request/src/azure_container/client_overhead/test/../optimize/proxy.py", line 30, in init
    with open(filename, 'r') as f:
FileNotFoundError: [Errno 2] No such file or directory: './main.py'
127.0.0.1 - - [2022-09-21 08:34:30] "POST /init HTTP/1.1" 500 401 0.005700
127.0.0.1 - - [2022-09-21 08:34:30] "POST /batch_run HTTP/1.1" 200 257 0.070412
[2022-09-21 08:34:30,835] ERROR in app: Exception on /init [POST]
Traceback (most recent call last):
  File "/home/vagrant/miniconda3/lib/python3.9/site-packages/flask/app.py", line 2525, in wsgi_app
    response = self.full_dispatch_request()
  File "/home/vagrant/miniconda3/lib/python3.9/site-packages/flask/app.py", line 1822, in full_dispatch_request
    rv = self.handle_user_exception(e)
  File "/home/vagrant/miniconda3/lib/python3.9/site-packages/flask/app.py", line 1820, in full_dispatch_request
    rv = self.dispatch_request()
  File "/home/vagrant/miniconda3/lib/python3.9/site-packages/flask/app.py", line 1796, in dispatch_request
    return self.ensure_sync(self.view_functions[rule.endpoint])(**view_args)
  File "/home/vagrant/batching-request/src/azure_container/client_overhead/test/../optimize/proxy.py", line 103, in init
    runner.init()
  File "/home/vagrant/batching-request/src/azure_container/client_overhead/test/../optimize/proxy.py", line 30, in init
    with open(filename, 'r') as f:
FileNotFoundError: [Errno 2] No such file or directory: './main.py'
127.0.0.1 - - [2022-09-21 08:34:30] "POST /init HTTP/1.1" 500 401 0.006073
127.0.0.1 - - [2022-09-21 08:34:30] "POST /batch_run HTTP/1.1" 200 339 0.093328
[2022-09-21 08:34:31,655] ERROR in app: Exception on /init [POST]
Traceback (most recent call last):
  File "/home/vagrant/miniconda3/lib/python3.9/site-packages/flask/app.py", line 2525, in wsgi_app
    response = self.full_dispatch_request()
  File "/home/vagrant/miniconda3/lib/python3.9/site-packages/flask/app.py", line 1822, in full_dispatch_request
    rv = self.handle_user_exception(e)
  File "/home/vagrant/miniconda3/lib/python3.9/site-packages/flask/app.py", line 1820, in full_dispatch_request
    rv = self.dispatch_request()
  File "/home/vagrant/miniconda3/lib/python3.9/site-packages/flask/app.py", line 1796, in dispatch_request
    return self.ensure_sync(self.view_functions[rule.endpoint])(**view_args)
  File "/home/vagrant/batching-request/src/azure_container/client_overhead/test/../optimize/proxy.py", line 103, in init
    runner.init()
  File "/home/vagrant/batching-request/src/azure_container/client_overhead/test/../optimize/proxy.py", line 30, in init
    with open(filename, 'r') as f:
FileNotFoundError: [Errno 2] No such file or directory: './main.py'
127.0.0.1 - - [2022-09-21 08:34:31] "POST /init HTTP/1.1" 500 401 0.005557
127.0.0.1 - - [2022-09-21 08:34:31] "POST /batch_run HTTP/1.1" 200 413 0.163522
[2022-09-21 08:34:32,548] ERROR in app: Exception on /init [POST]
Traceback (most recent call last):
  File "/home/vagrant/miniconda3/lib/python3.9/site-packages/flask/app.py", line 2525, in wsgi_app
    response = self.full_dispatch_request()
  File "/home/vagrant/miniconda3/lib/python3.9/site-packages/flask/app.py", line 1822, in full_dispatch_request
    rv = self.handle_user_exception(e)
  File "/home/vagrant/miniconda3/lib/python3.9/site-packages/flask/app.py", line 1820, in full_dispatch_request
    rv = self.dispatch_request()
  File "/home/vagrant/miniconda3/lib/python3.9/site-packages/flask/app.py", line 1796, in dispatch_request
    return self.ensure_sync(self.view_functions[rule.endpoint])(**view_args)
  File "/home/vagrant/batching-request/src/azure_container/client_overhead/test/../optimize/proxy.py", line 103, in init
    runner.init()
  File "/home/vagrant/batching-request/src/azure_container/client_overhead/test/../optimize/proxy.py", line 30, in init
    with open(filename, 'r') as f:
FileNotFoundError: [Errno 2] No such file or directory: './main.py'
127.0.0.1 - - [2022-09-21 08:34:32] "POST /init HTTP/1.1" 500 401 0.005777
127.0.0.1 - - [2022-09-21 08:34:32] "POST /batch_run HTTP/1.1" 200 497 0.245928
[2022-09-21 08:34:33,528] ERROR in app: Exception on /init [POST]
Traceback (most recent call last):
  File "/home/vagrant/miniconda3/lib/python3.9/site-packages/flask/app.py", line 2525, in wsgi_app
    response = self.full_dispatch_request()
  File "/home/vagrant/miniconda3/lib/python3.9/site-packages/flask/app.py", line 1822, in full_dispatch_request
    rv = self.handle_user_exception(e)
  File "/home/vagrant/miniconda3/lib/python3.9/site-packages/flask/app.py", line 1820, in full_dispatch_request
    rv = self.dispatch_request()
  File "/home/vagrant/miniconda3/lib/python3.9/site-packages/flask/app.py", line 1796, in dispatch_request
    return self.ensure_sync(self.view_functions[rule.endpoint])(**view_args)
  File "/home/vagrant/batching-request/src/azure_container/client_overhead/test/../optimize/proxy.py", line 103, in init
    runner.init()
  File "/home/vagrant/batching-request/src/azure_container/client_overhead/test/../optimize/proxy.py", line 30, in init
    with open(filename, 'r') as f:
FileNotFoundError: [Errno 2] No such file or directory: './main.py'
127.0.0.1 - - [2022-09-21 08:34:33] "POST /init HTTP/1.1" 500 401 0.005981
127.0.0.1 - - [2022-09-21 08:34:33] "POST /batch_run HTTP/1.1" 200 570 0.202263
[2022-09-21 08:34:34,450] ERROR in app: Exception on /init [POST]
Traceback (most recent call last):
  File "/home/vagrant/miniconda3/lib/python3.9/site-packages/flask/app.py", line 2525, in wsgi_app
    response = self.full_dispatch_request()
  File "/home/vagrant/miniconda3/lib/python3.9/site-packages/flask/app.py", line 1822, in full_dispatch_request
    rv = self.handle_user_exception(e)
  File "/home/vagrant/miniconda3/lib/python3.9/site-packages/flask/app.py", line 1820, in full_dispatch_request
    rv = self.dispatch_request()
  File "/home/vagrant/miniconda3/lib/python3.9/site-packages/flask/app.py", line 1796, in dispatch_request
    return self.ensure_sync(self.view_functions[rule.endpoint])(**view_args)
  File "/home/vagrant/batching-request/src/azure_container/client_overhead/test/../optimize/proxy.py", line 103, in init
    runner.init()
  File "/home/vagrant/batching-request/src/azure_container/client_overhead/test/../optimize/proxy.py", line 30, in init
    with open(filename, 'r') as f:
FileNotFoundError: [Errno 2] No such file or directory: './main.py'
127.0.0.1 - - [2022-09-21 08:34:34] "POST /init HTTP/1.1" 500 401 0.002260
127.0.0.1 - - [2022-09-21 08:34:34] "POST /batch_run HTTP/1.1" 200 642 0.281440
[2022-09-21 08:34:35,447] ERROR in app: Exception on /init [POST]
Traceback (most recent call last):
  File "/home/vagrant/miniconda3/lib/python3.9/site-packages/flask/app.py", line 2525, in wsgi_app
    response = self.full_dispatch_request()
  File "/home/vagrant/miniconda3/lib/python3.9/site-packages/flask/app.py", line 1822, in full_dispatch_request
    rv = self.handle_user_exception(e)
  File "/home/vagrant/miniconda3/lib/python3.9/site-packages/flask/app.py", line 1820, in full_dispatch_request
    rv = self.dispatch_request()
  File "/home/vagrant/miniconda3/lib/python3.9/site-packages/flask/app.py", line 1796, in dispatch_request
    return self.ensure_sync(self.view_functions[rule.endpoint])(**view_args)
  File "/home/vagrant/batching-request/src/azure_container/client_overhead/test/../optimize/proxy.py", line 103, in init
    runner.init()
  File "/home/vagrant/batching-request/src/azure_container/client_overhead/test/../optimize/proxy.py", line 30, in init
    with open(filename, 'r') as f:
FileNotFoundError: [Errno 2] No such file or directory: './main.py'
127.0.0.1 - - [2022-09-21 08:34:35] "POST /init HTTP/1.1" 500 401 0.006289
127.0.0.1 - - [2022-09-21 08:34:35] "POST /batch_run HTTP/1.1" 200 726 0.275698
[2022-09-21 08:34:36,440] ERROR in app: Exception on /init [POST]
Traceback (most recent call last):
  File "/home/vagrant/miniconda3/lib/python3.9/site-packages/flask/app.py", line 2525, in wsgi_app
    response = self.full_dispatch_request()
  File "/home/vagrant/miniconda3/lib/python3.9/site-packages/flask/app.py", line 1822, in full_dispatch_request
    rv = self.handle_user_exception(e)
  File "/home/vagrant/miniconda3/lib/python3.9/site-packages/flask/app.py", line 1820, in full_dispatch_request
    rv = self.dispatch_request()
  File "/home/vagrant/miniconda3/lib/python3.9/site-packages/flask/app.py", line 1796, in dispatch_request
    return self.ensure_sync(self.view_functions[rule.endpoint])(**view_args)
  File "/home/vagrant/batching-request/src/azure_container/client_overhead/test/../optimize/proxy.py", line 103, in init
    runner.init()
  File "/home/vagrant/batching-request/src/azure_container/client_overhead/test/../optimize/proxy.py", line 30, in init
    with open(filename, 'r') as f:
FileNotFoundError: [Errno 2] No such file or directory: './main.py'
127.0.0.1 - - [2022-09-21 08:34:36] "POST /init HTTP/1.1" 500 401 0.005383
127.0.0.1 - - [2022-09-21 08:34:37] "POST /batch_run HTTP/1.1" 200 805 0.663597
[2022-09-21 08:34:37,838] ERROR in app: Exception on /init [POST]
Traceback (most recent call last):
  File "/home/vagrant/miniconda3/lib/python3.9/site-packages/flask/app.py", line 2525, in wsgi_app
    response = self.full_dispatch_request()
  File "/home/vagrant/miniconda3/lib/python3.9/site-packages/flask/app.py", line 1822, in full_dispatch_request
    rv = self.handle_user_exception(e)
  File "/home/vagrant/miniconda3/lib/python3.9/site-packages/flask/app.py", line 1820, in full_dispatch_request
    rv = self.dispatch_request()
  File "/home/vagrant/miniconda3/lib/python3.9/site-packages/flask/app.py", line 1796, in dispatch_request
    return self.ensure_sync(self.view_functions[rule.endpoint])(**view_args)
  File "/home/vagrant/batching-request/src/azure_container/client_overhead/test/../optimize/proxy.py", line 103, in init
    runner.init()
  File "/home/vagrant/batching-request/src/azure_container/client_overhead/test/../optimize/proxy.py", line 30, in init
    with open(filename, 'r') as f:
FileNotFoundError: [Errno 2] No such file or directory: './main.py'
127.0.0.1 - - [2022-09-21 08:34:37] "POST /init HTTP/1.1" 500 401 0.005995
127.0.0.1 - - [2022-09-21 08:34:38] "POST /batch_run HTTP/1.1" 200 887 0.257883
[2022-09-21 08:35:35,147] ERROR in app: Exception on /init [POST]
Traceback (most recent call last):
  File "/home/vagrant/miniconda3/lib/python3.9/site-packages/flask/app.py", line 2525, in wsgi_app
    response = self.full_dispatch_request()
  File "/home/vagrant/miniconda3/lib/python3.9/site-packages/flask/app.py", line 1822, in full_dispatch_request
    rv = self.handle_user_exception(e)
  File "/home/vagrant/miniconda3/lib/python3.9/site-packages/flask/app.py", line 1820, in full_dispatch_request
    rv = self.dispatch_request()
  File "/home/vagrant/miniconda3/lib/python3.9/site-packages/flask/app.py", line 1796, in dispatch_request
    return self.ensure_sync(self.view_functions[rule.endpoint])(**view_args)
  File "/home/vagrant/batching-request/src/azure_container/client_overhead/test/../native/proxy.py", line 70, in init
    runner.init()
  File "/home/vagrant/batching-request/src/azure_container/client_overhead/test/../native/proxy.py", line 27, in init
    with open(filename, 'r') as f:
FileNotFoundError: [Errno 2] No such file or directory: './main.py'
127.0.0.1 - - [2022-09-21 08:35:35] "POST /init HTTP/1.1" 500 401 0.005834
127.0.0.1 - - [2022-09-21 08:35:35] "POST /batch_run HTTP/1.1" 200 189 0.100395
[2022-09-21 08:35:35,977] ERROR in app: Exception on /init [POST]
Traceback (most recent call last):
  File "/home/vagrant/miniconda3/lib/python3.9/site-packages/flask/app.py", line 2525, in wsgi_app
    response = self.full_dispatch_request()
  File "/home/vagrant/miniconda3/lib/python3.9/site-packages/flask/app.py", line 1822, in full_dispatch_request
    rv = self.handle_user_exception(e)
  File "/home/vagrant/miniconda3/lib/python3.9/site-packages/flask/app.py", line 1820, in full_dispatch_request
    rv = self.dispatch_request()
  File "/home/vagrant/miniconda3/lib/python3.9/site-packages/flask/app.py", line 1796, in dispatch_request
    return self.ensure_sync(self.view_functions[rule.endpoint])(**view_args)
  File "/home/vagrant/batching-request/src/azure_container/client_overhead/test/../native/proxy.py", line 70, in init
    runner.init()
  File "/home/vagrant/batching-request/src/azure_container/client_overhead/test/../native/proxy.py", line 27, in init
    with open(filename, 'r') as f:
FileNotFoundError: [Errno 2] No such file or directory: './main.py'
127.0.0.1 - - [2022-09-21 08:35:35] "POST /init HTTP/1.1" 500 401 0.006088
127.0.0.1 - - [2022-09-21 08:35:36] "POST /batch_run HTTP/1.1" 200 269 0.138664
[2022-09-21 08:35:36,832] ERROR in app: Exception on /init [POST]
Traceback (most recent call last):
  File "/home/vagrant/miniconda3/lib/python3.9/site-packages/flask/app.py", line 2525, in wsgi_app
    response = self.full_dispatch_request()
  File "/home/vagrant/miniconda3/lib/python3.9/site-packages/flask/app.py", line 1822, in full_dispatch_request
    rv = self.handle_user_exception(e)
  File "/home/vagrant/miniconda3/lib/python3.9/site-packages/flask/app.py", line 1820, in full_dispatch_request
    rv = self.dispatch_request()
  File "/home/vagrant/miniconda3/lib/python3.9/site-packages/flask/app.py", line 1796, in dispatch_request
    return self.ensure_sync(self.view_functions[rule.endpoint])(**view_args)
  File "/home/vagrant/batching-request/src/azure_container/client_overhead/test/../native/proxy.py", line 70, in init
    runner.init()
  File "/home/vagrant/batching-request/src/azure_container/client_overhead/test/../native/proxy.py", line 27, in init
    with open(filename, 'r') as f:
FileNotFoundError: [Errno 2] No such file or directory: './main.py'
127.0.0.1 - - [2022-09-21 08:35:36] "POST /init HTTP/1.1" 500 401 0.005875
127.0.0.1 - - [2022-09-21 08:35:37] "POST /batch_run HTTP/1.1" 200 352 0.231993
[2022-09-21 08:35:37,790] ERROR in app: Exception on /init [POST]
Traceback (most recent call last):
  File "/home/vagrant/miniconda3/lib/python3.9/site-packages/flask/app.py", line 2525, in wsgi_app
    response = self.full_dispatch_request()
  File "/home/vagrant/miniconda3/lib/python3.9/site-packages/flask/app.py", line 1822, in full_dispatch_request
    rv = self.handle_user_exception(e)
  File "/home/vagrant/miniconda3/lib/python3.9/site-packages/flask/app.py", line 1820, in full_dispatch_request
    rv = self.dispatch_request()
  File "/home/vagrant/miniconda3/lib/python3.9/site-packages/flask/app.py", line 1796, in dispatch_request
    return self.ensure_sync(self.view_functions[rule.endpoint])(**view_args)
  File "/home/vagrant/batching-request/src/azure_container/client_overhead/test/../native/proxy.py", line 70, in init
    runner.init()
  File "/home/vagrant/batching-request/src/azure_container/client_overhead/test/../native/proxy.py", line 27, in init
    with open(filename, 'r') as f:
FileNotFoundError: [Errno 2] No such file or directory: './main.py'
127.0.0.1 - - [2022-09-21 08:35:37] "POST /init HTTP/1.1" 500 401 0.005673
127.0.0.1 - - [2022-09-21 08:35:38] "POST /batch_run HTTP/1.1" 200 427 0.377084
[2022-09-21 08:35:38,890] ERROR in app: Exception on /init [POST]
Traceback (most recent call last):
  File "/home/vagrant/miniconda3/lib/python3.9/site-packages/flask/app.py", line 2525, in wsgi_app
    response = self.full_dispatch_request()
  File "/home/vagrant/miniconda3/lib/python3.9/site-packages/flask/app.py", line 1822, in full_dispatch_request
    rv = self.handle_user_exception(e)
  File "/home/vagrant/miniconda3/lib/python3.9/site-packages/flask/app.py", line 1820, in full_dispatch_request
    rv = self.dispatch_request()
  File "/home/vagrant/miniconda3/lib/python3.9/site-packages/flask/app.py", line 1796, in dispatch_request
    return self.ensure_sync(self.view_functions[rule.endpoint])(**view_args)
  File "/home/vagrant/batching-request/src/azure_container/client_overhead/test/../native/proxy.py", line 70, in init
    runner.init()
  File "/home/vagrant/batching-request/src/azure_container/client_overhead/test/../native/proxy.py", line 27, in init
    with open(filename, 'r') as f:
FileNotFoundError: [Errno 2] No such file or directory: './main.py'
127.0.0.1 - - [2022-09-21 08:35:38] "POST /init HTTP/1.1" 500 401 0.005573
127.0.0.1 - - [2022-09-21 08:35:39] "POST /batch_run HTTP/1.1" 200 507 0.568156
[2022-09-21 08:35:40,170] ERROR in app: Exception on /init [POST]
Traceback (most recent call last):
  File "/home/vagrant/miniconda3/lib/python3.9/site-packages/flask/app.py", line 2525, in wsgi_app
    response = self.full_dispatch_request()
  File "/home/vagrant/miniconda3/lib/python3.9/site-packages/flask/app.py", line 1822, in full_dispatch_request
    rv = self.handle_user_exception(e)
  File "/home/vagrant/miniconda3/lib/python3.9/site-packages/flask/app.py", line 1820, in full_dispatch_request
    rv = self.dispatch_request()
  File "/home/vagrant/miniconda3/lib/python3.9/site-packages/flask/app.py", line 1796, in dispatch_request
    return self.ensure_sync(self.view_functions[rule.endpoint])(**view_args)
  File "/home/vagrant/batching-request/src/azure_container/client_overhead/test/../native/proxy.py", line 70, in init
    runner.init()
  File "/home/vagrant/batching-request/src/azure_container/client_overhead/test/../native/proxy.py", line 27, in init
    with open(filename, 'r') as f:
FileNotFoundError: [Errno 2] No such file or directory: './main.py'
127.0.0.1 - - [2022-09-21 08:35:40] "POST /init HTTP/1.1" 500 401 0.005606
127.0.0.1 - - [2022-09-21 08:35:40] "POST /batch_run HTTP/1.1" 200 590 0.636162
[2022-09-21 08:35:41,535] ERROR in app: Exception on /init [POST]
Traceback (most recent call last):
  File "/home/vagrant/miniconda3/lib/python3.9/site-packages/flask/app.py", line 2525, in wsgi_app
    response = self.full_dispatch_request()
  File "/home/vagrant/miniconda3/lib/python3.9/site-packages/flask/app.py", line 1822, in full_dispatch_request
    rv = self.handle_user_exception(e)
  File "/home/vagrant/miniconda3/lib/python3.9/site-packages/flask/app.py", line 1820, in full_dispatch_request
    rv = self.dispatch_request()
  File "/home/vagrant/miniconda3/lib/python3.9/site-packages/flask/app.py", line 1796, in dispatch_request
    return self.ensure_sync(self.view_functions[rule.endpoint])(**view_args)
  File "/home/vagrant/batching-request/src/azure_container/client_overhead/test/../native/proxy.py", line 70, in init
    runner.init()
  File "/home/vagrant/batching-request/src/azure_container/client_overhead/test/../native/proxy.py", line 27, in init
    with open(filename, 'r') as f:
FileNotFoundError: [Errno 2] No such file or directory: './main.py'
127.0.0.1 - - [2022-09-21 08:35:41] "POST /init HTTP/1.1" 500 401 0.002808
127.0.0.1 - - [2022-09-21 08:35:42] "POST /batch_run HTTP/1.1" 200 670 1.239517
[2022-09-21 08:35:43,501] ERROR in app: Exception on /init [POST]
Traceback (most recent call last):
  File "/home/vagrant/miniconda3/lib/python3.9/site-packages/flask/app.py", line 2525, in wsgi_app
    response = self.full_dispatch_request()
  File "/home/vagrant/miniconda3/lib/python3.9/site-packages/flask/app.py", line 1822, in full_dispatch_request
    rv = self.handle_user_exception(e)
  File "/home/vagrant/miniconda3/lib/python3.9/site-packages/flask/app.py", line 1820, in full_dispatch_request
    rv = self.dispatch_request()
  File "/home/vagrant/miniconda3/lib/python3.9/site-packages/flask/app.py", line 1796, in dispatch_request
    return self.ensure_sync(self.view_functions[rule.endpoint])(**view_args)
  File "/home/vagrant/batching-request/src/azure_container/client_overhead/test/../native/proxy.py", line 70, in init
    runner.init()
  File "/home/vagrant/batching-request/src/azure_container/client_overhead/test/../native/proxy.py", line 27, in init
    with open(filename, 'r') as f:
FileNotFoundError: [Errno 2] No such file or directory: './main.py'
127.0.0.1 - - [2022-09-21 08:35:43] "POST /init HTTP/1.1" 500 401 0.005807
[2022-09-21 08:35:44,667] ERROR in app: Exception on /init [POST]
Traceback (most recent call last):
  File "/home/vagrant/miniconda3/lib/python3.9/site-packages/flask/app.py", line 2525, in wsgi_app
    response = self.full_dispatch_request()
  File "/home/vagrant/miniconda3/lib/python3.9/site-packages/flask/app.py", line 1822, in full_dispatch_request
    rv = self.handle_user_exception(e)
  File "/home/vagrant/miniconda3/lib/python3.9/site-packages/flask/app.py", line 1820, in full_dispatch_request
    rv = self.dispatch_request()
  File "/home/vagrant/miniconda3/lib/python3.9/site-packages/flask/app.py", line 1796, in dispatch_request
    return self.ensure_sync(self.view_functions[rule.endpoint])(**view_args)
  File "/home/vagrant/batching-request/src/azure_container/client_overhead/test/../native/proxy.py", line 70, in init
    runner.init()
  File "/home/vagrant/batching-request/src/azure_container/client_overhead/test/../native/proxy.py", line 27, in init
    with open(filename, 'r') as f:
FileNotFoundError: [Errno 2] No such file or directory: './main.py'
127.0.0.1 - - [2022-09-21 08:35:44] "POST /init HTTP/1.1" 500 401 0.006133
127.0.0.1 - - [2022-09-21 08:35:46] "POST /batch_run HTTP/1.1" 200 827 1.558509
